Workbook
Name _Toc179363803: #REF!
Name _Toc179363803: #REF!
Name _Toc224162412: #REF!
Name _Toc224162412: #REF!
Name 选中400: #REF!
Name 选中401: #REF!
Name 选中402: #REF!
Name 选中403: #REF!

Sheet 配方
A1: Modules/模块 | B1: Tech/工艺 | C1: Equipment/设备 | D1: Synthesis reactor/合成釜 | E1: Recipe parameter/配方参数 | F1: 氮气鼓泡 | G1: 搅拌 | H1: 保温 | I1: Activation tank/激活罐 | J1: Recipe parameter/配方参数 | K1: 搅拌 | L1: 保温 | M1: Time/次数 | N1: 配方物料名称 | O1: 配方投料量/kg | P1: 配方中误差值/kg | Q1: 辅助查询列 | R1: MOR 投料表 | S1: MOR投料表误差 | T1: 操作 | U1: 比对 | V1: 误差差值
A2: 3.0 Pre-treatment 预处理 | F2: =IFERROR(IF(FIND("开",F1,1),"开","关"),"关") -> 关 | G2: =IFERROR(IF(FIND("开",G1,1),"开","关"),"关") -> 关 | H2: =IFERROR(IF(FIND("开",H1,1),"开","关"),"关") -> 关 | K2: =IFERROR(IF(FIND("开",K1,1),"开","关"),"关") -> 关 | L2: =IFERROR(IF(FIND("开",L1,1),"开","关"),"关") -> 关 | T2: =IF(ISBLANK(A2),T1,LEFT(A2,FIND(" ",A2,1)-1)) -> 3.0
A3: 3.0(1) Water content/测水分 | B3: Add 369.85kg DMF（5.69W,6.0Vol）by spray balls into activation tank TJ4S-1213-Sy16-R01.Start the agitator of activation tank to 115±5 rpm (target: 115 rpm). Stir for 10min±5min (target: 10min). Then transfer the solution into synthesis reactor TJ4S-1213-Sy16. Confirm complete transfer. Turn on the nitrogen of synthesis reactor to 8.5±4m³/h (target: 8.5 m³/h). Start the agitator of synthesis reactor to 20±10rpm (target: 20 rpm). Stir for 10min±5min (target: 10min). Stop the stirring and turn off the nitrogen. Sample the draining solution for water content analysis.Start draining the solution from synthesis reactor with diaphramp pump. Drain until there is no drip, the operator visually confirms the draining end point.If KF≤500ppm, move to next operation. If KF>500 ppm, repeat Module 3.0 until KF≤500 ppm. 通过淋洗球向激活罐TJ4S-1213-Sy16-R01中加入369.85kg N,N-二甲基甲酰胺（5.69W,6.0Vol）（Acceptable weighing range/可接受称量范围：347.66kg~392.04kg），开启激活罐搅拌转速至115±5 rpm (目标转速: 115 rpm)。搅拌10min±5min（目标时间:10min）后，转移至固相合成釜TJ4S-1213-Sy16.中。开启合成釜下口鼓氮气，氮气流速开至8.5±4m³/h (目标流速: 8.5 m³/h)，开启固相合成釜搅拌转速至20±10 rpm (目标转速: 20 rpm)，搅拌10min±5min（目标时间:10min）后，停止搅拌，关闭氮气，取样检测体系KF，通过隔膜泵从合成釜中排出溶液。排液至无液体滴出，由操作人员目视确认排液终点。若含水≤500ppm，则进行下一操作；若含水＞500ppm，则重复进行模块3.0直至含水≤500ppm | C3: Activation tank/激活罐 | F3: =IFERROR(IF(FIND("开",F2,1),"开","关"),"关") -> 关 | G3: =IFERROR(IF(FIND("开",G2,1),"开","关"),"关") -> 关 | H3: =IFERROR(IF(FIND("开",H2,1),"开","关"),"关") -> 关 | I3: Rinse DMF_AT/DMF喷淋 | J3: [0min]Line-》DMF-Rinse->activation tank, weight setting: 369.85kg [0min] 线路-》DMF-喷淋->激活罐, 打料量：369.85kg | K3: =IFERROR(IF(FIND("开",K2,1),"开","关"),"关") -> 关 | L3: =IFERROR(IF(FIND("开",L2,1),"开","关"),"关") -> 关 | M3: 1 | N3: DMF | O3: =MID(J3,FIND("setting",J3,1)+8,FIND("kg",J3,1)-FIND("setting",J3,1)-8) -> 369.85 | Q3: =SUBSTITUTE(T3&N3," ","") -> 3DMF | R3: =VLOOKUP(Q3,MOR投料表!A:L,9,FALSE) -> 369.85 | T3: 3 | U3: =TEXT(O3,"0.00")=TEXT(R3,"0.00") -> TRUE
C4: Activation tank/激活罐 | F4: =IFERROR(IF(FIND("开",F3,1),"开","关"),"关") -> 关 | G4: =IFERROR(IF(FIND("开",G3,1),"开","关"),"关") -> 关 | H4: =IFERROR(IF(FIND("开",H3,1),"开","关"),"关") -> 关 | I4: Nitrogen_DMF/氮气吹扫-DMF喷淋 | J4: [0min]Line-》DMF Rinse-Nitrogen purge->activation tank, time setting: 0.1min [0min] 线路-》DMF-喷淋-氮气吹扫->激活罐, 打料时间：0.1min | K4: =IFERROR(IF(FIND("开",K3,1),"开","关"),"关") -> 关 | L4: =IFERROR(IF(FIND("开",L3,1),"开","关"),"关") -> 关 | T4: =IF(ISBLANK(A4),T3,LEFT(A4,FIND(" ",A4,1)-1)) -> 3
C5: Activation tank/激活罐 | F5: =IFERROR(IF(FIND("开",F4,1),"开","关"),"关") -> 关 | G5: =IFERROR(IF(FIND("开",G4,1),"开","关"),"关") -> 关 | H5: =IFERROR(IF(FIND("开",H4,1),"开","关"),"关") -> 关 | I5: Stir_AT/搅拌 | J5: [0min]activation tank agitator-》Speed setting: 115r/min, time setting: 10min [0min] 激活罐搅拌机-》转速：115r/min, 执行10min | K5: 时间控制 | L5: =IFERROR(IF(FIND("开",L4,1),"开","关"),"关") -> 关 | T5: =IF(ISBLANK(A5),T4,LEFT(A5,FIND(" ",A5,1)-1)) -> 3
C6: Synchronization/同步 | D6: Transfer AT_SR/转移 | E6: [0min]Line-》activation tank->synthesis reactor, according to human judgment. [0min] 线路-》激活罐->合成釜（人工判定）, 人工判定！, | F6: =IFERROR(IF(FIND("开",F5,1),"开","关"),"关") -> 关 | G6: =IFERROR(IF(FIND("开",G5,1),"开","关"),"关") -> 关 | H6: =IFERROR(IF(FIND("开",H5,1),"开","关"),"关") -> 关 | K6: =IFERROR(IF(FIND("开",K5,1),"开","关"),"关") -> 关 | L6: =IFERROR(IF(FIND("开",L5,1),"开","关"),"关") -> 关 | T6: =IF(ISBLANK(A6),T5,LEFT(A6,FIND(" ",A6,1)-1)) -> 3
C7: Synchronization/同步 | D7: Nitrogen_Transfer AT_SR/转移吹扫 | E7: [0min]Line-》Nitrogen purge for activation tank->synthesis reactor, time setting: 1min [0min] 线路-》激活罐-氮气吹扫->合成釜, 打料时间：1min | F7: =IFERROR(IF(FIND("开",F6,1),"开","关"),"关") -> 关 | G7: =IFERROR(IF(FIND("开",G6,1),"开","关"),"关") -> 关 | H7: =IFERROR(IF(FIND("开",H6,1),"开","关"),"关") -> 关 | K7: =IFERROR(IF(FIND("开",K6,1),"开","关"),"关") -> 关 | L7: =IFERROR(IF(FIND("开",L6,1),"开","关"),"关") -> 关 | T7: =IF(ISBLANK(A7),T6,LEFT(A7,FIND(" ",A7,1)-1)) -> 3
C8: Synthesis reactor/合成釜 | D8: Bubble_SR_On/氮气鼓泡开 | E8: [0min]Nitrogen bubbling -》Flow setting: 8.5m³/h, positive pressure, pressure setting: 0.005MPa, start-up [0min] 鼓氮气-》流量:8.5m³/h, 正压, 设定压力0.005Mpa,启动 | F8: 打开 | G8: =IFERROR(IF(FIND("开",G7,1),"开","关"),"关") -> 关 | H8: =IFERROR(IF(FIND("开",H7,1),"开","关"),"关") -> 关 | K8: =IFERROR(IF(FIND("开",K7,1),"开","关"),"关") -> 关 | L8: =IFERROR(IF(FIND("开",L7,1),"开","关"),"关") -> 关 | T8: =IF(ISBLANK(A8),T7,LEFT(A8,FIND(" ",A8,1)-1)) -> 3
C9: Synthesis reactor/合成釜 | D9: Stir_SR/搅拌 | E9: [0min]synthesis reactor agitator-》Speed setting: 20r/min, time setting: 10min [0min] 合成釜搅拌机-》转速：20r/min, 执行10min | F9: =IFERROR(IF(FIND("开",F8,1),"开","关"),"关") -> 开 | G9: 时间控制 | H9: =IFERROR(IF(FIND("开",H8,1),"开","关"),"关") -> 关 | K9: =IFERROR(IF(FIND("开",K8,1),"开","关"),"关") -> 关 | L9: =IFERROR(IF(FIND("开",L8,1),"开","关"),"关") -> 关 | T9: =IF(ISBLANK(A9),T8,LEFT(A9,FIND(" ",A9,1)-1)) -> 3
C10: Synthesis reactor/合成釜 | D10: Bubble_SR_Off/氮气鼓泡关 | E10: [0min]Nitrogen bubbling -》Flow setting: 8.5m³/h, positive pressure, pressure setting: 0.005MPa, shutdown [0min] 鼓氮气-》流量:8.5m³/h, 正压, 设定压力0.005Mpa,停止 | F10: 关闭 | G10: =IFERROR(IF(FIND("开",G9,1),"开","关"),"关") -> 关 | H10: =IFERROR(IF(FIND("开",H9,1),"开","关"),"关") -> 关 | K10: =IFERROR(IF(FIND("开",K9,1),"开","关"),"关") -> 关 | L10: =IFERROR(IF(FIND("开",L9,1),"开","关"),"关") -> 关 | T10: =IF(ISBLANK(A10),T9,LEFT(A10,FIND(" ",A10,1)-1)) -> 3
C11: Synthesis reactor/合成釜 | D11: Pause_SR/暂停-取样 | E11: Pause:Execution type : Parallel-synthesis reactor 暂停-》 控制类型：并行-合成釜 | F11: =IFERROR(IF(FIND("开",F10,1),"开","关"),"关") -> 关 | G11: =IFERROR(IF(FIND("开",G10,1),"开","关"),"关") -> 关 | H11: =IFERROR(IF(FIND("开",H10,1),"开","关"),"关") -> 关 | K11: =IFERROR(IF(FIND("开",K10,1),"开","关"),"关") -> 关 | L11: =IFERROR(IF(FIND("开",L10,1),"开","关"),"关") -> 关 | T11: =IF(ISBLANK(A11),T10,LEFT(A11,FIND(" ",A11,1)-1)) -> 3
C12: Synthesis reactor/合成釜 | D12: Drain_SR_Waste/排废 | E12: [0min]Line-》synthesis reactor->waste tank（1）, according to human judgement. [0min] 线路-》合成釜->废液罐（氨基酸活化后溶液&洗脱_人工判定）,人工判定！, | F12: =IFERROR(IF(FIND("开",F11,1),"开","关"),"关") -> 关 | G12: =IFERROR(IF(FIND("开",G11,1),"开","关"),"关") -> 关 | H12: =IFERROR(IF(FIND("开",H11,1),"开","关"),"关") -> 关 | K12: =IFERROR(IF(FIND("开",K11,1),"开","关"),"关") -> 关 | L12: =IFERROR(IF(FIND("开",L11,1),"开","关"),"关") -> 关 | T12: =IF(ISBLANK(A12),T11,LEFT(A12,FIND(" ",A12,1)-1)) -> 3
A13: ☐3.0 Pre-treatment 预处理 | F13: =IFERROR(IF(FIND("开",F12,1),"开","关"),"关") -> 关 | G13: =IFERROR(IF(FIND("开",G12,1),"开","关"),"关") -> 关 | H13: =IFERROR(IF(FIND("开",H12,1),"开","关"),"关") -> 关 | K13: =IFERROR(IF(FIND("开",K12,1),"开","关"),"关") -> 关 | L13: =IFERROR(IF(FIND("开",L12,1),"开","关"),"关") -> 关 | T13: =IF(ISBLANK(A13),T12,LEFT(A13,FIND(" ",A13,1)-1)) -> ☐3.0
A14: 3.0(2) Water content/测水分 | B14: Add 369.85kg DMF（5.69W,6.0Vol）by spray balls into activation tank TJ4S-1213-Sy16-R01.Start the agitator of activation tank to 115±5 rpm (target: 115 rpm). Stir for 10min±5min (target: 10min). Then transfer the solution into synthesis reactor TJ4S-1213-Sy16. Confirm complete transfer. Turn on the nitrogen of synthesis reactor to 8.5±4m³/h (target: 8.5 m³/h). Start the agitator of synthesis reactor to 20±10rpm (target: 20 rpm). Stir for 10min±5min (target: 10min). Stop the stirring and turn off the nitrogen. Sample the draining solution for water content analysis.Start draining the solution from synthesis reactor with diaphramp pump. Drain until there is no drip, the operator visually confirms the draining end point.If KF≤500ppm, move to next operation. If KF>500 ppm, repeat Module 3.0 until KF≤500 ppm. 通过淋洗球向激活罐TJ4S-1213-Sy16-R01中加入369.85kg N,N-二甲基甲酰胺（5.69W,6.0Vol）（Acceptable weighing range/可接受称量范围：347.66kg~392.04kg），开启激活罐搅拌转速至115±5 rpm (目标转速: 115 rpm)。搅拌10min±5min（目标时间:10min）后，转移至固相合成釜TJ4S-1213-Sy16.中。开启合成釜下口鼓氮气，氮气流速开至8.5±4m³/h (目标流速: 8.5 m³/h)，开启固相合成釜搅拌转速至20±10 rpm (目标转速: 20 rpm)，搅拌10min±5min（目标时间:10min）后，停止搅拌，关闭氮气，取样检测体系KF，通过隔膜泵从合成釜中排出溶液。排液至无液体滴出，由操作人员目视确认排液终点。若含水≤500ppm，则进行下一操作；若含水＞500ppm，则重复进行模块3.0直至含水≤500ppm | C14: Activation tank/激活罐 | F14: =IFERROR(IF(FIND("开",F13,1),"开","关"),"关") -> 关 | G14: =IFERROR(IF(FIND("开",G13,1),"开","关"),"关") -> 关 | H14: =IFERROR(IF(FIND("开",H13,1),"开","关"),"关") -> 关 | I14: Rinse DMF_AT/DMF喷淋 | J14: [0min]Line-》DMF-Rinse->activation tank, weight setting: 369.85kg [0min] 线路-》DMF-喷淋->激活罐, 打料量：369.85kg | K14: =IFERROR(IF(FIND("开",K13,1),"开","关"),"关") -> 关 | L14: =IFERROR(IF(FIND("开",L13,1),"开","关"),"关") -> 关 | M14: 1 | N14: DMF | O14: =MID(J14,FIND("setting",J14,1)+8,FIND("kg",J14,1)-FIND("setting",J14,1)-8) -> 369.85 | Q14: =SUBSTITUTE(T14&N14," ","") -> 3DMF | R14: =VLOOKUP(Q14,MOR投料表!A:L,9,FALSE) -> 369.85 | T14: 3 | U14: =TEXT(O14,"0.00")=TEXT(R14,"0.00") -> TRUE
C15: Activation tank/激活罐 | F15: =IFERROR(IF(FIND("开",F14,1),"开","关"),"关") -> 关 | G15: =IFERROR(IF(FIND("开",G14,1),"开","关"),"关") -> 关 | H15: =IFERROR(IF(FIND("开",H14,1),"开","关"),"关") -> 关 | I15: Nitrogen_DMF/氮气吹扫-DMF喷淋 | J15: [0min]Line-》DMF Rinse-Nitrogen purge->activation tank, time setting: 0.1min [0min] 线路-》DMF-喷淋-氮气吹扫->激活罐, 打料时间：0.1min | K15: =IFERROR(IF(FIND("开",K14,1),"开","关"),"关") -> 关 | L15: =IFERROR(IF(FIND("开",L14,1),"开","关"),"关") -> 关 | T15: =IF(ISBLANK(A15),T14,LEFT(A15,FIND(" ",A15,1)-1)) -> 3
C16: Activation tank/激活罐 | F16: =IFERROR(IF(FIND("开",F15,1),"开","关"),"关") -> 关 | G16: =IFERROR(IF(FIND("开",G15,1),"开","关"),"关") -> 关 | H16: =IFERROR(IF(FIND("开",H15,1),"开","关"),"关") -> 关 | I16: Stir_AT/搅拌 | J16: [0min]activation tank agitator-》Speed setting: 115r/min, time setting: 10min [0min] 激活罐搅拌机-》转速：115r/min, 执行10min | K16: 时间控制 | L16: =IFERROR(IF(FIND("开",L15,1),"开","关"),"关") -> 关 | T16: =IF(ISBLANK(A16),T15,LEFT(A16,FIND(" ",A16,1)-1)) -> 3
C17: Synchronization/同步 | D17: Transfer AT_SR/转移 | E17: [0min]Line-》activation tank->synthesis reactor, according to human judgment. [0min] 线路-》激活罐->合成釜（人工判定）, 人工判定！, | F17: =IFERROR(IF(FIND("开",F16,1),"开","关"),"关") -> 关 | G17: =IFERROR(IF(FIND("开",G16,1),"开","关"),"关") -> 关 | H17: =IFERROR(IF(FIND("开",H16,1),"开","关"),"关") -> 关 | K17: =IFERROR(IF(FIND("开",K16,1),"开","关"),"关") -> 关 | L17: =IFERROR(IF(FIND("开",L16,1),"开","关"),"关") -> 关 | T17: =IF(ISBLANK(A17),T16,LEFT(A17,FIND(" ",A17,1)-1)) -> 3
C18: Synchronization/同步 | D18: Nitrogen_Transfer AT_SR/转移吹扫 | E18: [0min]Line-》Nitrogen purge for activation tank->synthesis reactor, time setting: 1min [0min] 线路-》激活罐-氮气吹扫->合成釜, 打料时间：1min | F18: =IFERROR(IF(FIND("开",F17,1),"开","关"),"关") -> 关 | G18: =IFERROR(IF(FIND("开",G17,1),"开","关"),"关") -> 关 | H18: =IFERROR(IF(FIND("开",H17,1),"开","关"),"关") -> 关 | K18: =IFERROR(IF(FIND("开",K17,1),"开","关"),"关") -> 关 | L18: =IFERROR(IF(FIND("开",L17,1),"开","关"),"关") -> 关 | T18: =IF(ISBLANK(A18),T17,LEFT(A18,FIND(" ",A18,1)-1)) -> 3
C19: Synthesis reactor/合成釜 | D19: Bubble_SR_On/氮气鼓泡开 | E19: [0min]Nitrogen bubbling -》Flow setting: 8.5m³/h, positive pressure, pressure setting: 0.005MPa, start-up [0min] 鼓氮气-》流量:8.5m³/h, 正压, 设定压力0.005Mpa,启动 | F19: 打开 | G19: =IFERROR(IF(FIND("开",G18,1),"开","关"),"关") -> 关 | H19: =IFERROR(IF(FIND("开",H18,1),"开","关"),"关") -> 关 | K19: =IFERROR(IF(FIND("开",K18,1),"开","关"),"关") -> 关 | L19: =IFERROR(IF(FIND("开",L18,1),"开","关"),"关") -> 关 | T19: =IF(ISBLANK(A19),T18,LEFT(A19,FIND(" ",A19,1)-1)) -> 3
C20: Synthesis reactor/合成釜 | D20: Stir_SR/搅拌 | E20: [0min]synthesis reactor agitator-》Speed setting: 20r/min, time setting: 10min [0min] 合成釜搅拌机-》转速：20r/min, 执行10min | F20: =IFERROR(IF(FIND("开",F19,1),"开","关"),"关") -> 开 | G20: 时间控制 | H20: =IFERROR(IF(FIND("开",H19,1),"开","关"),"关") -> 关 | K20: =IFERROR(IF(FIND("开",K19,1),"开","关"),"关") -> 关 | L20: =IFERROR(IF(FIND("开",L19,1),"开","关"),"关") -> 关 | T20: =IF(ISBLANK(A20),T19,LEFT(A20,FIND(" ",A20,1)-1)) -> 3
C21: Synthesis reactor/合成釜 | D21: Bubble_SR_Off/氮气鼓泡关 | E21: [0min]Nitrogen bubbling -》Flow setting: 8.5m³/h, positive pressure, pressure setting: 0.005MPa, shutdown [0min] 鼓氮气-》流量:8.5m³/h, 正压, 设定压力0.005Mpa,停止 | F21: 关闭 | G21: =IFERROR(IF(FIND("开",G20,1),"开","关"),"关") -> 关 | H21: =IFERROR(IF(FIND("开",H20,1),"开","关"),"关") -> 关 | K21: =IFERROR(IF(FIND("开",K20,1),"开","关"),"关") -> 关 | L21: =IFERROR(IF(FIND("开",L20,1),"开","关"),"关") -> 关 | T21: =IF(ISBLANK(A21),T20,LEFT(A21,FIND(" ",A21,1)-1)) -> 3
C22: Synthesis reactor/合成釜 | D22: Pause_SR/暂停-取样 | E22: Pause:Execution type : Parallel-synthesis reactor 暂停-》 控制类型：并行-合成釜 | F22: =IFERROR(IF(FIND("开",F21,1),"开","关"),"关") -> 关 | G22: =IFERROR(IF(FIND("开",G21,1),"开","关"),"关") -> 关 | H22: =IFERROR(IF(FIND("开",H21,1),"开","关"),"关") -> 关 | K22: =IFERROR(IF(FIND("开",K21,1),"开","关"),"关") -> 关 | L22: =IFERROR(IF(FIND("开",L21,1),"开","关"),"关") -> 关 | T22: =IF(ISBLANK(A22),T21,LEFT(A22,FIND(" ",A22,1)-1)) -> 3
C23: Synthesis reactor/合成釜 | D23: Drain_SR_Waste/排废 | E23: [0min]Line-》synthesis reactor->waste tank（1）, according to human judgement. [0min] 线路-》合成釜->废液罐（氨基酸活化后溶液&洗脱_人工判定）,人工判定！, | F23: =IFERROR(IF(FIND("开",F22,1),"开","关"),"关") -> 关 | G23: =IFERROR(IF(FIND("开",G22,1),"开","关"),"关") -> 关 | H23: =IFERROR(IF(FIND("开",H22,1),"开","关"),"关") -> 关 | K23: =IFERROR(IF(FIND("开",K22,1),"开","关"),"关") -> 关 | L23: =IFERROR(IF(FIND("开",L22,1),"开","关"),"关") -> 关 | T23: =IF(ISBLANK(A23),T22,LEFT(A23,FIND(" ",A23,1)-1)) -> 3
A24: 3.1 to 3.4 （1）Fmoc-Gly-OH coupling 芴甲氧羰基-甘氨酸偶联 | F24: =IFERROR(IF(FIND("开",F23,1),"开","关"),"关") -> 关 | G24: =IFERROR(IF(FIND("开",G23,1),"开","关"),"关") -> 关 | H24: =IFERROR(IF(FIND("开",H23,1),"开","关"),"关") -> 关 | K24: =IFERROR(IF(FIND("开",K23,1),"开","关"),"关") -> 关 | L24: =IFERROR(IF(FIND("开",L23,1),"开","关"),"关") -> 关 | T24: =IF(ISBLANK(A24),T12,LEFT(A24,FIND(" ",A24,1)-1)) -> 3.1
A25: 3.1.1 to 3.1.5 Resin swelling/树脂溶胀 | B25: Adjust the synthesis reactor jacket temperature TJ4S-1213-Sy16 to 25±5℃ (target: 25℃). Add 65.00 kg 2-Chlorotrityl chloride resin (1.00eq) with powder feeding bags after dispensing. Rinse synthesis reactor (TJ4S-1213-Sy16) wall by spray balls with 492.70 kg (7.58W, 8.0Vol) DMF. Turn on the nitrogen of synthesis reactor to 8.5±4m³/h (target: 8.5 m³/h) .Bubble with nitrogen for 5±2min (target 5min). Then the agitator of synthesis reactor to 20±10rpm (target: 20 rpm). Adjust the internal temperature to 25±5℃ (target: 25℃). Continue stirring for 45±15min (target 45min) at 25±5℃ (target: 25℃), stop stirring, turn off the nitrogen. Start draining the solution from synthesis reactor with diaphramp pump. Drain until there is no drip, the operator visually confirms the draining end point. 将合成釜夹套调温至25±5℃ ( (目标温度：25℃) 。通过投料袋向合成釜 TJ4S-1213-Sy16中加入65.00kg 2-氯三苯甲基氯树脂（1.00eq）（Acceptable weighing range/可接受称量范围：64.87~65.13 kg）。通过淋洗球向合成釜（TJ4S-1213-Sy16）中加入492.70 kg（7.58W,8.0Vol）N,N-二甲基甲酰胺（Acceptable weighing range/可接受称量范围：463.14kg~522.26kg）。开启合成釜下口鼓氮气，氮气流速开至8.5±4m³/h (目标流速: 8.5 m³/h), 鼓氮气5±2min (目标时间：5min)后，开启固相合成釜搅拌转速至20±10 rpm (目标转速: 20 rpm)。将内温调温至25±5℃(目标温度：25℃)，控内温25±5℃(目标温度：25℃)，继续搅拌45±15min (目标时间：45min)后停止搅拌，关闭氮气，通过隔膜泵从合成釜中排出溶液。排液至无液体滴出，由操作人员目视确认排液终点。 | C25: Synthesis reactor/合成釜 | D25: JTR_SR_On/保温开 | E25: [0min]The jacket temperature of synthesis reactor-》Type: maintain, the jacket inlet temperature setting: 25℃, start-up [0min] 合成釜:控温-》类型：保温, 夹套进口温度设定值:25℃,启动 | F25: =IFERROR(IF(FIND("开",F24,1),"开","关"),"关") -> 关 | G25: =IFERROR(IF(FIND("开",G24,1),"开","关"),"关") -> 关 | H25: 打开 | K25: =IFERROR(IF(FIND("开",K24,1),"开","关"),"关") -> 关 | L25: =IFERROR(IF(FIND("开",L24,1),"开","关"),"关") -> 关 | M25: 1 | T25: =IF(ISBLANK(A25),T24,LEFT(A25,FIND(" ",A25,1)-1)) -> 3.1.1
C26: Activation tank/激活罐 | F26: =IFERROR(IF(FIND("开",F25,1),"开","关"),"关") -> 关 | G26: =IFERROR(IF(FIND("开",G25,1),"开","关"),"关") -> 关 | H26: =IFERROR(IF(FIND("开",H25,1),"开","关"),"关") -> 开 | I26: TCT_AT/温控计时 | J26: [0min]Temperature control timing of activation tank-》Temperature range setting: 0-30℃, time setting: 0.1min. Over-temperature warning L/H limit: 2/28℃ [0min] 激活罐:温控计时反应-》温度区间0-30℃环境下反应0.1min.预警下限/上限2/28℃ | K26: =IFERROR(IF(FIND("开",K25,1),"开","关"),"关") -> 关 | L26: =IFERROR(IF(FIND("开",L25,1),"开","关"),"关") -> 关 | T26: =IF(ISBLANK(A26),T25,LEFT(A26,FIND(" ",A26,1)-1)) -> 3.1.1
C27: Synthesis reactor/合成釜 | D27: Manual add 2-Chlorotrityl chloride resin_SR/手动投料 | E27: [0min]synthesis reactor: add by manual-》material: 2-Chlorotrityl chloride resin, weight setting: 65.00kg, weight error: 0.13kg [0min] 合成釜:手动投料-》物料：2-Chlorotrityl chloride resin，投料重量：65.00kg，重量误差±0.13kg | F27: =IFERROR(IF(FIND("开",F26,1),"开","关"),"关") -> 关 | G27: =IFERROR(IF(FIND("开",G26,1),"开","关"),"关") -> 关 | H27: =IFERROR(IF(FIND("开",H26,1),"开","关"),"关") -> 开 | K27: =IFERROR(IF(FIND("开",K26,1),"开","关"),"关") -> 关 | L27: =IFERROR(IF(FIND("开",L26,1),"开","关"),"关") -> 关 | N27: =MID(E27,FIND("物料",E27,1)+3,FIND("投料重量",E27,1)-FIND("物料",E27,1)-4) -> 2-Chlorotrityl chloride resin | O27: =MID(E27,FIND("setting",E27,1)+8,FIND("kg",E27,1)-FIND("setting",E27,1)-8) -> 65.00 | P27: =SUBSTITUTE(RIGHT(E27,LEN(E27)-FIND("重量误差",E27,1)-4),"kg","") -> 0.13 | Q27: =SUBSTITUTE(T27&N27," ","") -> 3.1.12-Chlorotritylchlorideresin | R27: =树脂信息!$C$4 -> 65 | T27: =IF(ISBLANK(A27),T26,LEFT(A27,FIND(" ",A27,1)-1)) -> 3.1.1 | U27: =TEXT(O27,"0.00")=TEXT(R27,"0.00") -> TRUE
C28: Synthesis reactor/合成釜 | D28: Add DMF_SR/DMF进料 | E28: [0min]Line-》DMF->synthesis reactor, weight setting: 492.70kg [0min] 线路-》DMF->合成釜, 打料量：492.70kg | F28: =IFERROR(IF(FIND("开",F27,1),"开","关"),"关") -> 关 | G28: =IFERROR(IF(FIND("开",G27,1),"开","关"),"关") -> 关 | H28: =IFERROR(IF(FIND("开",H27,1),"开","关"),"关") -> 开 | K28: =IFERROR(IF(FIND("开",K27,1),"开","关"),"关") -> 关 | L28: =IFERROR(IF(FIND("开",L27,1),"开","关"),"关") -> 关 | N28: DMF | O28: =MID(E28,FIND("setting",E28,1)+8,FIND("kg",E28,1)-FIND("setting",E28,1)-8) -> 492.70 | Q28: =SUBSTITUTE(T28&N28," ","") -> 3.1.3DMF | R28: =VLOOKUP(Q28,MOR投料表!A:L,9,FALSE) -> 492.7 | T28: 3.1.3 | U28: =TEXT(O28,"0.00")=TEXT(R28,"0.00") -> TRUE
C29: Synthesis reactor/合成釜 | D29: Nitrogen_DMF/氮气吹扫-DMF | E29: [0min]Line-》Nitrogen purge-DMF->synthesis reactor: time setting: 0.1min [0min] 线路-》DMF-氮气吹扫->合成釜, 打料时间：0.1min | F29: =IFERROR(IF(FIND("开",F28,1),"开","关"),"关") -> 关 | G29: =IFERROR(IF(FIND("开",G28,1),"开","关"),"关") -> 关 | H29: =IFERROR(IF(FIND("开",H28,1),"开","关"),"关") -> 开 | K29: =IFERROR(IF(FIND("开",K28,1),"开","关"),"关") -> 关 | L29: =IFERROR(IF(FIND("开",L28,1),"开","关"),"关") -> 关 | T29: =IF(ISBLANK(A29),T28,LEFT(A29,FIND(" ",A29,1)-1)) -> 3.1.3
C30: Synthesis reactor/合成釜 | D30: Bubble_SR_On/氮气鼓泡开 | E30: [0min]Nitrogen bubbling -》Flow setting: 8.5m³/h, positive pressure, pressure setting: 0.005MPa, start-up [0min] 鼓氮气-》流量:8.5m³/h, 正压, 设定压力0.005Mpa,启动 | F30: 打开 | G30: =IFERROR(IF(FIND("开",G29,1),"开","关"),"关") -> 关 | H30: =IFERROR(IF(FIND("开",H29,1),"开","关"),"关") -> 开 | K30: =IFERROR(IF(FIND("开",K29,1),"开","关"),"关") -> 关 | L30: =IFERROR(IF(FIND("开",L29,1),"开","关"),"关") -> 关 | T30: =IF(ISBLANK(A30),T29,LEFT(A30,FIND(" ",A30,1)-1)) -> 3.1.3
C31: Synthesis reactor/合成釜 | D31: Stir_SR_On/搅拌开 | E31: [5min]synthesis reactor agitator-》Speed setting: 20r/min, start-up [5min] 合成釜搅拌机-》转速：20r/min,启动 | F31: =IFERROR(IF(FIND("开",F30,1),"开","关"),"关") -> 开 | G31: 打开 | H31: =IFERROR(IF(FIND("开",H30,1),"开","关"),"关") -> 开 | K31: =IFERROR(IF(FIND("开",K30,1),"开","关"),"关") -> 关 | L31: =IFERROR(IF(FIND("开",L30,1),"开","关"),"关") -> 关 | T31: =IF(ISBLANK(A31),T30,LEFT(A31,FIND(" ",A31,1)-1)) -> 3.1.3
C32: Synthesis reactor/合成釜 | D32: TCT_SR/确认达到温度范围 | E32: [0min]Temperature control timing of synthesis reactor-》Temperature range setting: 21-29℃, time setting: 0.1min.Over-temperature warning L/H limit: 22/28℃ [0min] 合成釜:温控计时反应-》温度区间21-29℃环境下反应0.1min.预警下限/上限22/28℃ | F32: =IFERROR(IF(FIND("开",F31,1),"开","关"),"关") -> 开 | G32: =IFERROR(IF(FIND("开",G31,1),"开","关"),"关") -> 开 | H32: =IFERROR(IF(FIND("开",H31,1),"开","关"),"关") -> 开 | K32: =IFERROR(IF(FIND("开",K31,1),"开","关"),"关") -> 关 | L32: =IFERROR(IF(FIND("开",L31,1),"开","关"),"关") -> 关 | T32: =IF(ISBLANK(A32),T31,LEFT(A32,FIND(" ",A32,1)-1)) -> 3.1.3
C33: Synthesis reactor/合成釜 | D33: TCT_SR/温控计时 | E33: [0min]Temperature control timing of synthesis reactor-》Temperature range setting: 20-30℃, time setting: 45min. Over-temperature warning L/H limit: 22/28℃ [0min] 合成釜:温控计时反应-》温度区间20-30℃环境下反应45min.预警下限/上限22/28℃ | F33: =IFERROR(IF(FIND("开",F32,1),"开","关"),"关") -> 开 | G33: =IFERROR(IF(FIND("开",G32,1),"开","关"),"关") -> 开 | H33: =IFERROR(IF(FIND("开",H32,1),"开","关"),"关") -> 开 | K33: =IFERROR(IF(FIND("开",K32,1),"开","关"),"关") -> 关 | L33: =IFERROR(IF(FIND("开",L32,1),"开","关"),"关") -> 关 | T33: =IF(ISBLANK(A33),T32,LEFT(A33,FIND(" ",A33,1)-1)) -> 3.1.3
C34: Synthesis reactor/合成釜 | D34: Stir_SR_Off/搅拌关 | E34: [0min]synthesis reactor agitator-》Speed setting: 20r/min, shutdown [0min] 合成釜搅拌机-》转速：20r/min,停止 | F34: =IFERROR(IF(FIND("开",F33,1),"开","关"),"关") -> 开 | G34: 关闭 | H34: =IFERROR(IF(FIND("开",H33,1),"开","关"),"关") -> 开 | K34: =IFERROR(IF(FIND("开",K33,1),"开","关"),"关") -> 关 | L34: =IFERROR(IF(FIND("开",L33,1),"开","关"),"关") -> 关 | T34: =IF(ISBLANK(A34),T33,LEFT(A34,FIND(" ",A34,1)-1)) -> 3.1.3
C35: Synthesis reactor/合成釜 | D35: Bubble_SR_Off/氮气鼓泡关 | E35: [0min]Nitrogen bubbling -》Flow setting: 8.5m³/h, positive pressure, pressure setting: 0.005MPa, shutdown [0min] 鼓氮气-》流量:8.5m³/h, 正压, 设定压力0.005Mpa,停止 | F35: 关闭 | G35: =IFERROR(IF(FIND("开",G34,1),"开","关"),"关") -> 关 | H35: =IFERROR(IF(FIND("开",H34,1),"开","关"),"关") -> 开 | K35: =IFERROR(IF(FIND("开",K34,1),"开","关"),"关") -> 关 | L35: =IFERROR(IF(FIND("开",L34,1),"开","关"),"关") -> 关 | T35: =IF(ISBLANK(A35),T34,LEFT(A35,FIND(" ",A35,1)-1)) -> 3.1.3
C36: Synthesis reactor/合成釜 | D36: Drain_SR_Waste/排废 | E36: [0min]Line-》synthesis reactor->waste tank（1）, according to human judgement. [0min] 线路-》合成釜->废液罐（氨基酸活化后溶液&洗脱_人工判定）,人工判定！, | F36: =IFERROR(IF(FIND("开",F35,1),"开","关"),"关") -> 关 | G36: =IFERROR(IF(FIND("开",G35,1),"开","关"),"关") -> 关 | H36: =IFERROR(IF(FIND("开",H35,1),"开","关"),"关") -> 开 | K36: =IFERROR(IF(FIND("开",K35,1),"开","关"),"关") -> 关 | L36: =IFERROR(IF(FIND("开",L35,1),"开","关"),"关") -> 关 | T36: =IF(ISBLANK(A36),T35,LEFT(A36,FIND(" ",A36,1)-1)) -> 3.1.3
A37: 3.1.6 to 3.1.8 Dissolve/溶解 | B37: Adjust the jacket temperature of activation tank TJ4S-1213-Sy16-R01 to 25±5℃ (target: 25℃). Add 369.85kg DMF (5.69W, 6vol) by spray balls into the activation tank TJ4S-1213-Sy16-R01. Start the agitator of activation tank to 115±5 rpm (target: 115 rpm). Add Fmoc-Gly-OH with powder feeding bags into the activation tank TJ4S-1213-Sy16-R01. Rinse the port of the activation tank TJ4S-1213-Sy16-R01 with 61.75kg (0.95W, 1.0vol) DMF by spray balls. Adjust internal temperature of the mixture to 15±5℃. Continue agitation of activation tank to 115±5 rpm (target: 115 rpm). Maintain stirring for NLT 15min at 15±5℃ (target: 15℃).Confirm no visible solids and later use. 将激活罐TJ4S-1213-Sy16-R01夹套调温至25±5℃（目标温度：25℃）。向激活罐TJ4S-1213-Sy16-R01中加入369.85kg N,N-二甲基甲酰胺（5.69W, 6.0vol）（Acceptable weighing range/可接受称量范围：351.36kg~388.34kg），开启激活罐搅拌转速至115±5 rpm (目标转速: 115 rpm)。通过投料袋向激活罐TJ4S-1213-Sy16-R01中加入_________ kg芴甲氧羰基-甘氨酸（2.25eq）（Acceptable weighing range//可接受称量范围：_________ kg ~_________ kg）。通过淋洗球用61.75kg N,N-二甲基甲酰胺（0.95W, 1.0vol）（Acceptable weighing range/可接受称量范围：58.05kg~65.46kg）淋洗激活罐投料口。内温调温至15±5℃。控内温15±5℃（目标温度:15℃），维持激活罐搅拌转速至115±5 rpm (目标转速: 115 rpm)，继续搅拌至少15min，确认无明显固体，待用。 | C37: Activation tank/激活罐 | F37: =IFERROR(IF(FIND("开",F36,1),"开","关"),"关") -> 关 | G37: =IFERROR(IF(FIND("开",G36,1),"开","关"),"关") -> 关 | H37: =IFERROR(IF(FIND("开",H36,1),"开","关"),"关") -> 开 | I37: JTR_AT_On/保温开 | J37: [0min]The jacket temperature of activation tank-》Type: maintain, the jacket temperature setting: 25℃, start-up [0min] 激活罐:控温-》类型：保温, 夹套进口温度设定值:25℃,启动 | K37: =IFERROR(IF(FIND("开",K36,1),"开","关"),"关") -> 关 | L37: =IFERROR(IF(FIND("开",L36,1),"开","关"),"关") -> 关 | M37: 1 | N37: DMF | O37: =MID(J37,FIND("setting",J37,1)+8,FIND("kg",J37,1)-FIND("setting",J37,1)-8) -> #VALUE! | Q37: =SUBSTITUTE(T37&N37," ","") -> 3.1.6DMF | R37: =VLOOKUP(Q37,MOR投料表!A:L,9,FALSE) -> 369.85 | T37: =IF(ISBLANK(A37),T36,LEFT(A37,FIND(" ",A37,1)-1)) -> 3.1.6 | U37: =TEXT(O37,"0.00")=TEXT(R37,"0.00") -> #VALUE!
C38: Activation tank/激活罐 | I38: Add DMF_AT/DMF进料 | J38: [0min]Line-》DMF-Rinse->activation tank, weight setting: 369.85kg [0min] 线路-》DMF-喷淋->激活罐, 打料量：369.85kg | N38: DMF | O38: =MID(J38,FIND("setting",J38,1)+8,FIND("kg",J38,1)-FIND("setting",J38,1)-8) -> 369.85 | Q38: =SUBSTITUTE(T38&N38," ","") -> 3DMF | R38: =VLOOKUP(Q38,MOR投料表!A:L,9,FALSE) -> 369.85 | T38: 3 | U38: =TEXT(O38,"0.00")=TEXT(R38,"0.00") -> TRUE
C39: Activation tank/激活罐 | F39: =IFERROR(IF(FIND("开",F37,1),"开","关"),"关") -> 关 | G39: =IFERROR(IF(FIND("开",G37,1),"开","关"),"关") -> 关 | H39: =IFERROR(IF(FIND("开",H37,1),"开","关"),"关") -> 开 | I39: Nitrogen_DMF/氮气吹扫-DMF | J39: [0min]Line-》DMF Rinse-Nitrogen purge->activation tank, time setting: 0.1min [0min] 线路-》DMF-喷淋-氮气吹扫->激活罐, 打料时间：0.1min | K39: =IFERROR(IF(FIND("开",K37,1),"开","关"),"关") -> 关 | L39: =IFERROR(IF(FIND("开",L37,1),"开","关"),"关") -> 关 | T39: =IF(ISBLANK(A39),T37,LEFT(A39,FIND(" ",A39,1)-1)) -> 3.1.6
C40: Activation tank/激活罐 | F40: =IFERROR(IF(FIND("开",F39,1),"开","关"),"关") -> 关 | G40: =IFERROR(IF(FIND("开",G39,1),"开","关"),"关") -> 关 | H40: =IFERROR(IF(FIND("开",H39,1),"开","关"),"关") -> 开 | I40: Stir_AT_On/搅拌开 | J40: [0min]Activation tank agitator-》Speed setting: 115r/min, start-up [0min] 激活罐搅拌机-》转速：115r/min,启动 | K40: 打开 | L40: =IFERROR(IF(FIND("开",L39,1),"开","关"),"关") -> 关 | T40: =IF(ISBLANK(A40),T39,LEFT(A40,FIND(" ",A40,1)-1)) -> 3.1.6
...

Sheet 树脂信息
A1: 103.35 | B1: Raw Material Name/ | C1: Standard Batch Qty/ | D1: Standard Batch Amount of Substance/ | E1: Weighing accuracy/ | F1: Acceptable weighing range/ | G1: Qty Charged/ | J1: 黄色底纹需录入
A2: 操作指令编号 | B2: 原料名称 | C2: 标准投料量（kg） | D2: 投料总摩尔量（mol） | E2: 称量精确度 | F2: 可接受称量范围（kg） | G2: 实际投料量 | J2: 绿色底纹自动生成
G3: （kg） | J3: 固定用量，根据所选反应釜体积修改
A4: 1.1/3.1.1* | B4: Sieber Amide resin/ Sieber树脂 | C4: 65 | D4: =ROUND(C4*B8,2) -> 102.7 | E4: ±0.2% | J4: 特殊要求
B5: Raw Material of Substitution/取代度 （mmol/g） | D5: Entered by & Date/ 填写人及日期： | F5: =C4-ROUND(C4*0.002,2) -> 64.87
B8: 1.58 | F8: ~
D11: Reviewed by & Date/ 复核人及日期： | F11: =C4+ROUND(C4*0.002,2) -> 65.13
A15: .
A17: Non-Limiting material/非基准物料：

Sheet 氨基酸和溶剂信息
B1: Operation Instruction No.操作指令编号 | C1: Raw Material Name原料名称 | D1: Mol. Wt. of material/原料分子量 | E1: Density/密度（g/cm3） | F1: Mol Ratio to limiting material/与基准原料摩尔比 | G1: Qty Ratio to limiting material/ 与基准原料质量比 | H1: Standard Batch Qty标准投料量*（kg） | I1: Weighing accuracy/称量精确度 | J1: Acceptable weighing range 可接受称量范围（kg） | L1: Qty Charged实际投料量（Kg） | M1: 投料上下限误差 | N1: MOR当量 | O1: Molar Eqyivalent/摩尔当量 | P1: 体积比 | Q1: 文本 | T1: 公式 | U1: 序号 | W1: 计划量文本 | X1: 辅助1 | Y1: 辅助2 | Z1: 计划量公式 | AB1: 分装文本 | AC1: 投料顺序文本
A2: =IFERROR(SUBSTITUTE(IFERROR(MID(B2,FIND("/",B2,1)+1,LEN(B2)),B2)&LEFT(C2,FIND("/",C2,1)-1)," ",""),"") -> 3DMF | B2: 3 | C2: DMF/N, N-二甲基甲酰胺 | D2: 73.1 | E2: 0.948 | F2: - | G2: 5.69 | H2: =TEXT(ROUND(G2*树脂信息!$C$4,2),"0.00") -> 369.85 | I2: ±6% | J2: =TEXT(ROUND(H2*0.94,2),"0.00")&"~"&TEXT(ROUND(H2*1.06,2),"0.00") -> 347.66~392.04 | P2: 6
A3: =IFERROR(SUBSTITUTE(IFERROR(MID(B3,FIND("/",B3,1)+1,LEN(B3)),B3)&LEFT(C3,FIND("/",C3,1)-1)," ",""),"") -> 3DMF | B3: 3 | C3: DMF/N, N-二甲基甲酰胺 | D3: 73.1 | E3: 0.948 | F3: - | G3: 5.69 | H3: =TEXT(ROUND(G3*树脂信息!$C$4,2),"0.00") -> 369.85 | I3: ±6% | J3: =TEXT(ROUND(H3*0.94,2),"0.00")&"~"&TEXT(ROUND(H3*1.06,2),"0.00") -> 347.66~392.04 | P3: 6
A4: =IFERROR(SUBSTITUTE(IFERROR(MID(B4,FIND("/",B4,1)+1,LEN(B4)),B4)&LEFT(C4,FIND("/",C4,1)-1)," ",""),"") -> 3.1.3DMF | B4: 3.1.3 | C4: DMF/N, N-二甲基甲酰胺 | D4: 73.1 | E4: 0.948 | F4: - | G4: 7.58 | H4: =TEXT(ROUND(G4*树脂信息!$C$4,2),"0.00") -> 492.70 | I4: ±6% | J4: =TEXT(ROUND(H4*0.94,2),"0.00")&"~"&TEXT(ROUND(H4*1.06,2),"0.00") -> 463.14~522.26 | P4: 8
A5: =IFERROR(SUBSTITUTE(IFERROR(MID(B5,FIND("/",B5,1)+1,LEN(B5)),B5)&LEFT(C5,FIND("/",C5,1)-1)," ",""),"") -> 3.1.6DMF | B5: 3.1.6 | C5: DMF/N, N-二甲基甲酰胺 | D5: 73.1 | E5: 0.948 | F5: - | G5: 5.69 | H5: =TEXT(ROUND(G5*树脂信息!$C$4,2),"0.00") -> 369.85 | I5: ±5% | J5: =TEXT(ROUND(H5*0.95,2),"0.00")&"~"&TEXT(ROUND(H5*1.05,2),"0.00") -> 351.36~388.34 | P5: 6
A6: =IFERROR(SUBSTITUTE(IFERROR(MID(B6,FIND("/",B6,1)+1,LEN(B6)),B6)&LEFT(C6,FIND("/",C6,1)-1)," ",""),"") -> 3.1.7Fmoc-Gly-OH | B6: 1.2/3.1.7 | C6: Fmoc-Gly-OH/芴甲氧羰基-甘氨酸 | D6: 297.31 | E6: - | F6: =O6 -> 2.25 | G6: - | H6: =ROUND(O6*D6/1000*树脂信息!$D$4,2) -> 68.7 | I6: ±3.0% | J6: =TEXT(ROUND(H6*0.97,2),"0.00")&"~"&TEXT(ROUND(H6*1.03,2),"0.00") -> 66.64~70.76 | K6: =ROUND(H6*0.03,2) -> 2.06 | M6: =(H6-H6*0.97)+(H6-H6*1.03) -> 0 | N6: 2.25 | O6: 2.25 | Q6: ="Ins "&B6&" The standard batch Qty of "&LEFT(C6,FIND("/",C6,1)-1)&"/操作"&LEFT(B6,FIND("/",B6,1)-1)&"（用于Ins."&MID(B6,FIND("/",B6,1)+1,100)&"）"&MID(C6,FIND("/",C6,1)+1,100)&"标准投料量" -> Ins 1.2/3.1.7 The standard batch Qty of Fmoc-Gly-OH/操作1.2（用于Ins.3.1.7）芴甲氧羰基-甘氨酸标准投料量 | R6: sclRoundMV(convertToMeasuredValue( convertTo(PH:{Standard Batch Moles/投料总摩尔量}.{1 Value},"mol")* | S6: ,"kg"),2,"HALF_UP") | T6: =R6&#REF!&S6 -> #REF! | U6: =COUNTIF(#REF!,_xlfn.IFNA(S6,#REF!))+1 -> #REF! | V6: =U6-1 -> #REF! | W6: ="Update Ins "&MID(B6,FIND("/",B6,1)+1,100)&" plan qty of "&LEFT(C6,FIND("/",C6,1)-1)&"/更新操作"&MID(B6,FIND("/",B6,1)+1,100)&" "&MID(C6,FIND("/",C6,1)+1,100)&"计划量" -> Update Ins 3.1.7 plan qty of Fmoc-Gly-OH/更新操作3.1.7 芴甲氧羰基-甘氨酸计划量 | X6: updateWeighingPlanQuantity(" | Y6: -1", PH:{Standard batch Qty calculation/标准投料量计算-01}.{ | Z6: =X6&MID(B6,FIND("/",B6,1)+1,100)&Y6&U6&" Value})" -> #REF! | AB6: ="Ins "&LEFT(B6,FIND("/",B6,1)-1)&" Dispense "&LEFT(C6,FIND("/",C6,1)-1)&"/分装"&MID(C6,FIND("/",C6,1)+1,100) -> Ins 1.2 Dispense Fmoc-Gly-OH/分装芴甲氧羰基-甘氨酸 | AC6: =MID(B6,FIND("/",B6,1)+1,100)&" "&C6 -> 3.1.7 Fmoc-Gly-OH/芴甲氧羰基-甘氨酸
A7: =IFERROR(SUBSTITUTE(IFERROR(MID(B7,FIND("/",B7,1)+1,LEN(B7)),B7)&LEFT(C7,FIND("/",C7,1)-1)," ",""),"") -> 3.1.8DMF | B7: 3.1.8 | C7: DMF/N, N-二甲基甲酰胺 | D7: 73.1 | E7: 0.948 | F7: - | G7: 0.95 | H7: =TEXT(ROUND(G7*树脂信息!$C$4,2),"0.00") -> 61.75 | I7: ±6% | J7: =TEXT(ROUND(H7*0.94,2),"0.00")&"~"&TEXT(ROUND(H7*1.06,2),"0.00") -> 58.05~65.46 | P7: 1
A8: =IFERROR(SUBSTITUTE(IFERROR(MID(B8,FIND("/",B8,1)+1,LEN(B8)),B8)&LEFT(C8,FIND("/",C8,1)-1)," ",""),"") -> 3.1.9DMF | B8: 3.1.9 | C8: DMF/N, N-二甲基甲酰胺 | D8: 73.1 | E8: 0.948 | F8: - | G8: 4.74 | H8: =TEXT(ROUND(G8*树脂信息!$C$4,2),"0.00") -> 308.10 | I8: ±6% | J8: =TEXT(ROUND(H8*0.94,2),"0.00")&"~"&TEXT(ROUND(H8*1.06,2),"0.00") -> 289.61~326.59 | P8: 5
A9: =IFERROR(SUBSTITUTE(IFERROR(MID(B9,FIND("/",B9,1)+1,LEN(B9)),B9)&LEFT(C9,FIND("/",C9,1)-1)," ",""),"") -> 3.2.1DIPEA | B9: 3.2.1 | C9: DIPEA/N,N-二异丙基乙胺 | D9: 129.24 | E9: - | F9: =O9 -> 6 | G9: - | H9: =ROUND(O9*D9/1000*树脂信息!$D$4,2) -> 79.64 | I9: ±3.0% | J9: =TEXT(ROUND(H9*0.97,2),"0.00")&"~"&TEXT(ROUND(H9*1.03,2),"0.00") -> 77.25~82.03 | K9: =ROUND(H9*0.03,2) -> 2.39 | M9: =(H9-H9*0.97)+(H9-H9*1.03) -> 0 | N9: 6 | O9: 6
A10: =IFERROR(SUBSTITUTE(IFERROR(MID(B10,FIND("/",B10,1)+1,LEN(B10)),B10)&LEFT(C10,FIND("/",C10,1)-1)," ",""),"") -> 3.3.2DMF | B10: 3.3.2 | C10: DMF/N, N-二甲基甲酰胺 | D10: 73.1 | E10: 0.948 | F10: - | G10: 0.95 | H10: =TEXT(ROUND(G10*树脂信息!$C$4,2),"0.00") -> 61.75 | I10: ±6% | J10: =TEXT(ROUND(H10*0.94,2),"0.00")&"~"&TEXT(ROUND(H10*1.06,2),"0.00") -> 58.05~65.46 | P10: 1
A11: =IFERROR(SUBSTITUTE(IFERROR(MID(B11,FIND("/",B11,1)+1,LEN(B11)),B11)&LEFT(C11,FIND("/",C11,1)-1)," ",""),"") -> 3.3.6DMF | B11: 3.3.6 | C11: DMF/N, N-二甲基甲酰胺 | D11: 73.1 | E11: 0.948 | F11: - | G11: 7.58 | H11: =TEXT(ROUND(G11*树脂信息!$C$4,2),"0.00") -> 492.70 | I11: ±6% | J11: =TEXT(ROUND(H11*0.94,2),"0.00")&"~"&TEXT(ROUND(H11*1.06,2),"0.00") -> 463.14~522.26 | L11: See below/见下行 | P11: 8
D12: Qty Charged/实际投料量（kg）：1st： kg；2nd： kg；3rd： kg； | Q12: 缺少激活罐洗涤
A13: =IFERROR(SUBSTITUTE(IFERROR(MID(B13,FIND("/",B13,1)+1,LEN(B13)),B13)&LEFT(C13,FIND("/",C13,1)-1)," ",""),"") -> 3.4.1DMF | B13: 3.4.1 | C13: DMF/N, N-二甲基甲酰胺 | D13: 73.1 | E13: 0.948 | F13: - | G13: 8.53 | H13: =TEXT(ROUND(G13*树脂信息!$C$4,2),"0.00") -> 554.45 | I13: ±6% | J13: =TEXT(ROUND(H13*0.94,2),"0.00")&"~"&TEXT(ROUND(H13*1.06,2),"0.00") -> 521.18~587.72 | P13: 9
A14: =IFERROR(SUBSTITUTE(IFERROR(MID(B14,FIND("/",B14,1)+1,LEN(B14)),B14)&LEFT(C14,FIND("/",C14,1)-1)," ",""),"") -> 3.4.2Methanol | B14: 3.4.2 | C14: Methanol/甲醇 | D14: 32.01 | E14: - | F14: =O14 -> 10 | G14: - | H14: =ROUND(O14*D14/1000*树脂信息!$D$4,2) -> 32.87 | I14: ±3.0% | J14: =TEXT(ROUND(H14*0.97,2),"0.00")&"~"&TEXT(ROUND(H14*1.03,2),"0.00") -> 31.88~33.86 | K14: =ROUND(H14*0.03,2) -> 0.99 | M14: =(H14-H14*0.97)+(H14-H14*1.03) -> 0 | N14: 10 | O14: 10 | Q14: ="Ins "&B14&" The standard batch Qty of "&LEFT(C14,FIND("/",C14,1)-1)&"/操作"&B14&" "&MID(C14,FIND("/",C14,1)+1,100)&"标准投料量" -> Ins 3.4.2 The standard batch Qty of Methanol/操作3.4.2 甲醇标准投料量 | R14: sclRoundMV(convertToMeasuredValue( convertTo(PH:{Standard Batch Moles/投料总摩尔量}.{1 Value},"mol")* | S14: ,"kg"),2,"HALF_UP") | T14: =R14&#REF!&S14 -> #REF! | U14: =COUNTIF($S$9:S14,_xlfn.IFNA(S14,$S$9:S14))+1 -> 2 | V14: =U14-1 -> 1 | W14: ="Update Ins "&B14&" plan qty of "&LEFT(C14,FIND("/",C14,1)-1)&"/更新操作"&B14&" "&MID(C14,FIND("/",C14,1)+1,100)&"计划量" -> Update Ins 3.4.2 plan qty of Methanol/更新操作3.4.2 甲醇计划量 | X14: updateWeighingPlanQuantity(" | Y14: -1", PH:{Standard batch Qty calculation/标准投料量计算-01}.{ | Z14: =X14&B14&Y14&U14&" Value})" -> updateWeighingPlanQuantity("3.4.2-1", PH:{Standard batch Qty calculation/标准投料量计算-01}.{2 Value}) | AB14: ="Ins "&B14&" Weighing of "&LEFT(C14,FIND("/",C14,1)-1)&"/"&MID(C14,FIND("/",C14,1)+1,100)&"称重" -> Ins 3.4.2 Weighing of Methanol/甲醇称重
A15: =IFERROR(SUBSTITUTE(IFERROR(MID(B15,FIND("/",B15,1)+1,LEN(B15)),B15)&LEFT(C15,FIND("/",C15,1)-1)," ",""),"") -> 3.4.3DIPEA | B15: 3.4.3 | C15: DIPEA/N,N-二异丙基乙胺 | D15: 129.24 | E15: - | F15: =O15 -> 5 | G15: - | H15: =ROUND(O15*D15/1000*树脂信息!$D$4,2) -> 66.36 | I15: ±3.0% | J15: =TEXT(ROUND(H15*0.97,2),"0.00")&"~"&TEXT(ROUND(H15*1.03,2),"0.00") -> 64.37~68.35 | K15: =ROUND(H15*0.03,2) -> 1.99 | M15: =(H15-H15*0.97)+(H15-H15*1.03) -> 0 | N15: 5 | O15: 5 | Q15: ="Ins "&B15&" The standard batch Qty of "&LEFT(C15,FIND("/",C15,1)-1)&"/操作"&B15&" "&MID(C15,FIND("/",C15,1)+1,100)&"标准投料量" -> Ins 3.4.3 The standard batch Qty of DIPEA/操作3.4.3 N,N-二异丙基乙胺标准投料量 | R15: sclRoundMV(convertToMeasuredValue( convertTo(PH:{Standard Batch Moles/投料总摩尔量}.{1 Value},"mol")* | S15: ,"kg"),2,"HALF_UP") | T15: =R15&#REF!&S15 -> #REF! | U15: =COUNTIF($S$9:S15,_xlfn.IFNA(S15,$S$9:S15))+1 -> 3 | V15: =U15-1 -> 2 | W15: ="Update Ins "&B15&" plan qty of "&LEFT(C15,FIND("/",C15,1)-1)&"/更新操作"&B15&" "&MID(C15,FIND("/",C15,1)+1,100)&"计划量" -> Update Ins 3.4.3 plan qty of DIPEA/更新操作3.4.3 N,N-二异丙基乙胺计划量 | X15: updateWeighingPlanQuantity(" | Y15: -3", PH:{Standard batch Qty calculation/标准投料量计算-01}.{ | Z15: =X15&B15&Y15&U15&" Value})" -> updateWeighingPlanQuantity("3.4.3-3", PH:{Standard batch Qty calculation/标准投料量计算-01}.{3 Value}) | AB15: ="Ins "&B15&" Weighing of "&LEFT(C15,FIND("/",C15,1)-1)&"/"&MID(C15,FIND("/",C15,1)+1,100)&"称重" -> Ins 3.4.3 Weighing of DIPEA/N,N-二异丙基乙胺称重
A16: =IFERROR(SUBSTITUTE(IFERROR(MID(B16,FIND("/",B16,1)+1,LEN(B16)),B16)&LEFT(C16,FIND("/",C16,1)-1)," ",""),"") -> 3.4.6DMF | B16: 3.4.6 | C16: DMF/N, N-二甲基甲酰胺 | D16: 73.1 | E16: 0.948 | F16: - | G16: 7.58 | H16: =TEXT(ROUND(G16*树脂信息!$C$4,2),"0.00") -> 492.70 | I16: ±6% | J16: =TEXT(ROUND(H16*0.94,2),"0.00")&"~"&TEXT(ROUND(H16*1.06,2),"0.00") -> 463.14~522.26 | L16: See below/见下行 | P16: 8
A17: =IFERROR(SUBSTITUTE(IFERROR(MID(B17,FIND("/",B17,1)+1,LEN(B17)),B17)&LEFT(C17,FIND("/",C17,1)-1)," ",""),"") | D17: Qty Charged/实际投料量（kg）：1st： kg；2nd： kg；3rd： kg； | Q17: 缺少激活罐洗涤
A18: =IFERROR(SUBSTITUTE(IFERROR(MID(B18,FIND("/",B18,1)+1,LEN(B18)),B18)&LEFT(C18,FIND("/",C18,1)-1)," ",""),"") | B18: （2）Fmoc-L-Thr(tBu)-OH/芴甲氧羰基-叔丁基-L-苏氨酸
A19: =IFERROR(SUBSTITUTE(IFERROR(MID(B19,FIND("/",B19,1)+1,LEN(B19)),B19)&LEFT(C19,FIND("/",C19,1)-1)," ",""),"") -> 3.5.120%piperidinesolution | B19: 3.5.1 | C19: 20% piperidine solution/20%哌啶溶液 | D19: - | E19: 0.931 | F19: - | G19: 7.44 | H19: =TEXT(ROUND(G19*树脂信息!$C$4,2),"0.00") -> 483.60 | I19: ±6% | J19: =TEXT(ROUND(H19*0.94,2),"0.00")&"~"&TEXT(ROUND(H19*1.06,2),"0.00") -> 454.58~512.62 | L19: See below/见下行 | P19: 8 | Q19: 20%哌啶溶液密度待确认
A20: =IFERROR(SUBSTITUTE(IFERROR(MID(B20,FIND("/",B20,1)+1,LEN(B20)),B20)&LEFT(C20,FIND("/",C20,1)-1)," ",""),"") -> 3.5.4IPAC | B20: 3.5.4 | C20: IPAC/乙酸异丙酯 | E20: 0.873 | F20: - | G20: 6.98 | H20: =TEXT(ROUND(G20*树脂信息!$C$4,2),"0.00") -> 453.70 | I20: ±6% | J20: =TEXT(ROUND(H20*0.94,2),"0.00")&"~"&TEXT(ROUND(H20*1.06,2),"0.00") -> 426.48~480.92 | L20: See below/见下行 | P20: 8
A21: =IFERROR(SUBSTITUTE(IFERROR(MID(B21,FIND("/",B21,1)+1,LEN(B21)),B21)&LEFT(C21,FIND("/",C21,1)-1)," ",""),"") | D21: Qty Charged/实际投料量（kg）：1st： kg；2nd： kg；3rd： kg；4th： kg；
A22: =IFERROR(SUBSTITUTE(IFERROR(MID(B22,FIND("/",B22,1)+1,LEN(B22)),B22)&LEFT(C22,FIND("/",C22,1)-1)," ",""),"") -> 3.5.5DMF | B22: 3.5.5 | C22: DMF/N, N-二甲基甲酰胺 | D22: 73.1 | E22: 0.948 | F22: - | G22: 7.58 | H22: =TEXT(ROUND(G22*树脂信息!$C$4,2),"0.00") -> 492.70 | I22: ±6% | J22: =TEXT(ROUND(H22*0.94,2),"0.00")&"~"&TEXT(ROUND(H22*1.06,2),"0.00") -> 463.14~522.26 | P22: 8
A23: =IFERROR(SUBSTITUTE(IFERROR(MID(B23,FIND("/",B23,1)+1,LEN(B23)),B23)&LEFT(C23,FIND("/",C23,1)-1)," ",""),"") -> 3.5.7DMF | B23: 3.5.7 | C23: DMF/N, N-二甲基甲酰胺 | D23: 73.1 | E23: 0.948 | F23: - | G23: 7.58 | H23: =TEXT(ROUND(G23*树脂信息!$C$4,2),"0.00") -> 492.70 | I23: ±6% | J23: =TEXT(ROUND(H23*0.94,2),"0.00")&"~"&TEXT(ROUND(H23*1.06,2),"0.00") -> 463.14~522.26 | P23: 8
A24: =IFERROR(SUBSTITUTE(IFERROR(MID(B24,FIND("/",B24,1)+1,LEN(B24)),B24)&LEFT(C24,FIND("/",C24,1)-1)," ",""),"") -> 3.6.1DMF | B24: 3.6.1 | C24: DMF/N, N-二甲基甲酰胺 | D24: 73.1 | E24: 0.948 | F24: - | G24: 3.79 | H24: =TEXT(ROUND(G24*树脂信息!$C$4,2),"0.00") -> 246.35 | I24: ±5% | J24: =TEXT(ROUND(H24*0.95,2),"0.00")&"~"&TEXT(ROUND(H24*1.05,2),"0.00") -> 234.03~258.67 | P24: 4
A25: =IFERROR(SUBSTITUTE(IFERROR(MID(B25,FIND("/",B25,1)+1,LEN(B25)),B25)&LEFT(C25,FIND("/",C25,1)-1)," ",""),"") -> 3.6.2Fmoc-L-Thr(tBu)-OH | B25: 1.3/3.6.2 | C25: Fmoc-L-Thr(tBu)-OH/芴甲氧羰基-叔丁基-L-苏氨酸 | D25: 397.46 | E25: - | F25: =O25 -> 2 | G25: - | H25: =ROUND(O25*D25/1000*树脂信息!$D$4,2) -> 81.64 | I25: ±3.0% | J25: =TEXT(ROUND(H25*0.97,2),"0.00")&"~"&TEXT(ROUND(H25*1.03,2),"0.00") -> 79.19~84.09 | K25: =ROUND(H25*0.03,2) -> 2.45 | M25: =(H25-H25*0.97)+(H25-H25*1.03) -> 0 | N25: 2 | O25: 2 | Q25: ="Ins "&B25&" The standard batch Qty of "&LEFT(C25,FIND("/",C25,1)-1)&"/操作"&LEFT(B25,FIND("/",B25,1)-1)&"（用于Ins."&MID(B25,FIND("/",B25,1)+1,100)&"）"&MID(C25,FIND("/",C25,1)+1,100)&"标准投料量" -> Ins 1.3/3.6.2 The standard batch Qty of Fmoc-L-Thr(tBu)-OH/操作1.3（用于Ins.3.6.2）芴甲氧羰基-叔丁基-L-苏氨酸标准投料量 | R25: sclRoundMV(convertToMeasuredValue( convertTo(PH:{Standard Batch Moles/投料总摩尔量}.{1 Value},"mol")* | S25: ,"kg"),2,"HALF_UP") | T25: =R25&#REF!&S25 -> #REF! | U25: =COUNTIF($S$9:S25,_xlfn.IFNA(S25,$S$9:S25))+1 -> 4 | V25: =U25-1 -> 3 | W25: ="Update Ins "&MID(B25,FIND("/",B25,1)+1,100)&" plan qty of "&LEFT(C25,FIND("/",C25,1)-1)&"/更新操作"&MID(B25,FIND("/",B25,1)+1,100)&" "&MID(C25,FIND("/",C25,1)+1,100)&"计划量" -> Update Ins 3.6.2 plan qty of Fmoc-L-Thr(tBu)-OH/更新操作3.6.2 芴甲氧羰基-叔丁基-L-苏氨酸计划量 | X25: updateWeighingPlanQuantity(" | Y25: -1", PH:{Standard batch Qty calculation/标准投料量计算-01}.{ | Z25: =X25&MID(B25,FIND("/",B25,1)+1,100)&Y25&U25&" Value})" -> updateWeighingPlanQuantity("3.6.2-1", PH:{Standard batch Qty calculation/标准投料量计算-01}.{4 Value}) | AB25: ="Ins "&LEFT(B25,FIND("/",B25,1)-1)&" Dispense "&LEFT(C25,FIND("/",C25,1)-1)&"/分装"&MID(C25,FIND("/",C25,1)+1,100) -> Ins 1.3 Dispense Fmoc-L-Thr(tBu)-OH/分装芴甲氧羰基-叔丁基-L-苏氨酸 | AC25: =MID(B25,FIND("/",B25,1)+1,100)&" "&C25 -> 3.6.2 Fmoc-L-Thr(tBu)-OH/芴甲氧羰基-叔丁基-L-苏氨酸
A26: =IFERROR(SUBSTITUTE(IFERROR(MID(B26,FIND("/",B26,1)+1,LEN(B26)),B26)&LEFT(C26,FIND("/",C26,1)-1)," ",""),"") -> 3.6.4PyBOP | B26: 1.4/3.6.4 | C26: PyBOP/1H-苯并三唑-1-基氧三吡咯烷基六氟磷酸盐 | D26: 520.39 | E26: - | F26: =O26 -> 2 | G26: - | H26: =ROUND(O26*D26/1000*树脂信息!$D$4,2) -> 106.89 | I26: ±3.0% | J26: =TEXT(ROUND(H26*0.97,2),"0.00")&"~"&TEXT(ROUND(H26*1.03,2),"0.00") -> 103.68~110.10 | K26: =ROUND(H26*0.03,2) -> 3.21 | M26: =(H26-H26*0.97)+(H26-H26*1.03) -> 0 | N26: 2 | O26: 2 | Q26: ="Ins "&B26&" The standard batch Qty of "&LEFT(C26,FIND("/",C26,1)-1)&"/操作"&LEFT(B26,FIND("/",B26,1)-1)&"（用于Ins."&MID(B26,FIND("/",B26,1)+1,100)&"）"&MID(C26,FIND("/",C26,1)+1,100)&"标准投料量" -> Ins 1.4/3.6.4 The standard batch Qty of PyBOP/操作1.4（用于Ins.3.6.4）1H-苯并三唑-1-基氧三吡咯烷基六氟磷酸盐标准投料量 | R26: sclRoundMV(convertToMeasuredValue( convertTo(PH:{Standard Batch Moles/投料总摩尔量}.{1 Value},"mol")* | S26: ,"kg"),2,"HALF_UP") | T26: =R26&#REF!&S26 -> #REF! | U26: =COUNTIF($S$9:S26,_xlfn.IFNA(S26,$S$9:S26))+1 -> 5 | V26: =U26-1 -> 4 | W26: ="Update Ins "&MID(B26,FIND("/",B26,1)+1,100)&" plan qty of "&LEFT(C26,FIND("/",C26,1)-1)&"/更新操作"&MID(B26,FIND("/",B26,1)+1,100)&" "&MID(C26,FIND("/",C26,1)+1,100)&"计划量" -> Update Ins 3.6.4 plan qty of PyBOP/更新操作3.6.4 1H-苯并三唑-1-基氧三吡咯烷基六氟磷酸盐计划量 | X26: updateWeighingPlanQuantity(" | Y26: -1", PH:{Standard batch Qty calculation/标准投料量计算-01}.{ | Z26: =X26&MID(B26,FIND("/",B26,1)+1,100)&Y26&U26&" Value})" -> updateWeighingPlanQuantity("3.6.4-1", PH:{Standard batch Qty calculation/标准投料量计算-01}.{5 Value}) | AB26: ="Ins "&LEFT(B26,FIND("/",B26,1)-1)&" Dispense "&LEFT(C26,FIND("/",C26,1)-1)&"/分装"&MID(C26,FIND("/",C26,1)+1,100) -> Ins 1.4 Dispense PyBOP/分装1H-苯并三唑-1-基氧三吡咯烷基六氟磷酸盐 | AC26: =MID(B26,FIND("/",B26,1)+1,100)&" "&C26 -> 3.6.4 PyBOP/1H-苯并三唑-1-基氧三吡咯烷基六氟磷酸盐
A27: =IFERROR(SUBSTITUTE(IFERROR(MID(B27,FIND("/",B27,1)+1,LEN(B27)),B27)&LEFT(C27,FIND("/",C27,1)-1)," ",""),"") -> 3.6.5Oxymapure | B27: 1.5/3.6.5 | C27: Oxyma pure/2-肟氰乙酸乙酯 | D27: 142.11 | E27: - | F27: =O27 -> 2 | G27: - | H27: =ROUND(O27*D27/1000*树脂信息!$D$4,2) -> 29.19 | I27: ±3.0% | J27: =TEXT(ROUND(H27*0.97,2),"0.00")&"~"&TEXT(ROUND(H27*1.03,2),"0.00") -> 28.31~30.07 | K27: =ROUND(H27*0.03,2) -> 0.88 | M27: =(H27-H27*0.97)+(H27-H27*1.03) -> 0 | N27: 2 | O27: 2 | Q27: ="Ins "&B27&" The standard batch Qty of "&LEFT(C27,FIND("/",C27,1)-1)&"/操作"&LEFT(B27,FIND("/",B27,1)-1)&"（用于Ins."&MID(B27,FIND("/",B27,1)+1,100)&"）"&MID(C27,FIND("/",C27,1)+1,100)&"标准投料量" -> Ins 1.5/3.6.5 The standard batch Qty of Oxyma pure/操作1.5（用于Ins.3.6.5）2-肟氰乙酸乙酯标准投料量 | R27: sclRoundMV(convertToMeasuredValue( convertTo(PH:{Standard Batch Moles/投料总摩尔量}.{1 Value},"mol")* | S27: ,"kg"),2,"HALF_UP") | T27: =R27&#REF!&S27 -> #REF! | U27: =COUNTIF($S$9:S27,_xlfn.IFNA(S27,$S$9:S27))+1 -> 6 | V27: =U27-1 -> 5 | W27: ="Update Ins "&MID(B27,FIND("/",B27,1)+1,100)&" plan qty of "&LEFT(C27,FIND("/",C27,1)-1)&"/更新操作"&MID(B27,FIND("/",B27,1)+1,100)&" "&MID(C27,FIND("/",C27,1)+1,100)&"计划量" -> Update Ins 3.6.5 plan qty of Oxyma pure/更新操作3.6.5 2-肟氰乙酸乙酯计划量 | X27: updateWeighingPlanQuantity(" | Y27: -3", PH:{Standard batch Qty calculation/标准投料量计算-01}.{ | Z27: =X27&MID(B27,FIND("/",B27,1)+1,100)&Y27&U27&" Value})" -> updateWeighingPlanQuantity("3.6.5-3", PH:{Standard batch Qty calculation/标准投料量计算-01}.{6 Value}) | AB27: ="Ins "&LEFT(B27,FIND("/",B27,1)-1)&" Dispense "&LEFT(C27,FIND("/",C27,1)-1)&"/分装"&MID(C27,FIND("/",C27,1)+1,100) -> Ins 1.5 Dispense Oxyma pure/分装2-肟氰乙酸乙酯 | AC27: =MID(B27,FIND("/",B27,1)+1,100)&" "&C27 -> 3.6.5 Oxyma pure/2-肟氰乙酸乙酯
A28: =IFERROR(SUBSTITUTE(IFERROR(MID(B28,FIND("/",B28,1)+1,LEN(B28)),B28)&LEFT(C28,FIND("/",C28,1)-1)," ",""),"") -> 3.6.6DMF | B28: 3.6.6 | C28: DMF/N, N-二甲基甲酰胺 | D28: 73.1 | E28: 0.948 | F28: - | G28: 0.95 | H28: =TEXT(ROUND(G28*树脂信息!$C$4,2),"0.00") -> 61.75 | I28: ±6% | J28: =TEXT(ROUND(H28*0.94,2),"0.00")&"~"&TEXT(ROUND(H28*1.06,2),"0.00") -> 58.05~65.46 | P28: 1
A29: =IFERROR(SUBSTITUTE(IFERROR(MID(B29,FIND("/",B29,1)+1,LEN(B29)),B29)&LEFT(C29,FIND("/",C29,1)-1)," ",""),"") -> 3.6.7DIPEA | B29: 3.6.7 | C29: DIPEA/N,N-二异丙基乙胺 | D29: 129.24 | E29: - | F29: =O29 -> 3 | G29: - | H29: =ROUND(O29*D29/1000*树脂信息!$D$4,2) -> 39.82 | I29: ±3.0% | J29: =TEXT(ROUND(H29*0.97,2),"0.00")&"~"&TEXT(ROUND(H29*1.03,2),"0.00") -> 38.63~41.01 | K29: =ROUND(H29*0.03,2) -> 1.19 | M29: =(H29-H29*0.97)+(H29-H29*1.03) -> 0 | N29: 3 | O29: 3 | Q29: ="Ins "&B29&" The standard batch Qty of "&LEFT(C29,FIND("/",C29,1)-1)&"/操作"&B29&MID(C29,FIND("/",C29,1)+1,100)&"标准投料量" -> Ins 3.6.7 The standard batch Qty of DIPEA/操作3.6.7N,N-二异丙基乙胺标准投料量 | R29: sclRoundMV(convertToMeasuredValue( convertTo(PH:{Standard Batch Moles/投料总摩尔量}.{1 Value},"mol")* | S29: ,"kg"),2,"HALF_UP") | T29: =R29&#REF!&S29 -> #REF! | U29: =COUNTIF($S$9:S29,_xlfn.IFNA(S29,$S$9:S29))+1 -> 7 | V29: =U29-1 -> 6 | W29: ="Update Ins "&B29&" plan qty of "&LEFT(C29,FIND("/",C29,1)-1)&"/更新操作"&B29&" "&MID(C29,FIND("/",C29,1)+1,100)&"计划量" -> Update Ins 3.6.7 plan qty of DIPEA/更新操作3.6.7 N,N-二异丙基乙胺计划量 | X29: updateWeighingPlanQuantity(" | Y29: -1", PH:{Standard batch Qty calculation/标准投料量计算-01}.{ | Z29: =X29&B29&Y29&U29&" Value})" -> updateWeighingPlanQuantity("3.6.7-1", PH:{Standard batch Qty calculation/标准投料量计算-01}.{7 Value})
A30: =IFERROR(SUBSTITUTE(IFERROR(MID(B30,FIND("/",B30,1)+1,LEN(B30)),B30)&LEFT(C30,FIND("/",C30,1)-1)," ",""),"") -> 3.7.1DMF | B30: 3.7.1 | C30: DMF/N, N-二甲基甲酰胺 | D30: 73.1 | E30: 0.948 | F30: - | G30: 2.84 | H30: =TEXT(ROUND(G30*树脂信息!$C$4,2),"0.00") -> 184.60 | I30: ±6% | J30: =TEXT(ROUND(H30*0.94,2),"0.00")&"~"&TEXT(ROUND(H30*1.06,2),"0.00") -> 173.52~195.68 | P30: 3
A31: =IFERROR(SUBSTITUTE(IFERROR(MID(B31,FIND("/",B31,1)+1,LEN(B31)),B31)&LEFT(C31,FIND("/",C31,1)-1)," ",""),"") -> 3.7.3DMF | B31: 3.7.3 | C31: DMF/N, N-二甲基甲酰胺 | D31: 73.1 | E31: 0.948 | F31: - | G31: 0.95 | H31: =TEXT(ROUND(G31*树脂信息!$C$4,2),"0.00") -> 61.75 | I31: ±6% | J31: =TEXT(ROUND(H31*0.94,2),"0.00")&"~"&TEXT(ROUND(H31*1.06,2),"0.00") -> 58.05~65.46 | P31: 1
A32: =IFERROR(SUBSTITUTE(IFERROR(MID(B32,FIND("/",B32,1)+1,LEN(B32)),B32)&LEFT(C32,FIND("/",C32,1)-1)," ",""),"") -> 3.7.7DMF | B32: 3.7.7 | C32: DMF/N, N-二甲基甲酰胺 | D32: 73.1 | E32: 0.948 | F32: - | G32: 7.58 | H32: =TEXT(ROUND(G32*树脂信息!$C$4,2),"0.00") -> 492.70 | I32: ±6% | J32: =TEXT(ROUND(H32*0.94,2),"0.00")&"~"&TEXT(ROUND(H32*1.06,2),"0.00") -> 463.14~522.26 | L32: See below/见下行 | P32: 8
A33: =IFERROR(SUBSTITUTE(IFERROR(MID(B33,FIND("/",B33,1)+1,LEN(B33)),B33)&LEFT(C33,FIND("/",C33,1)-1)," ",""),"") | D33: Qty Charged/实际投料量（kg）：1st： kg；2nd： kg；3rd： kg；
A34: =IFERROR(SUBSTITUTE(IFERROR(MID(B34,FIND("/",B34,1)+1,LEN(B34)),B34)&LEFT(C34,FIND("/",C34,1)-1)," ",""),"") | B34: （3）Fmoc-L-Ala-OH·H2O/芴甲氧羰基-L-丙氨酸一水合物 | F34: -
A35: =IFERROR(SUBSTITUTE(IFERROR(MID(B35,FIND("/",B35,1)+1,LEN(B35)),B35)&LEFT(C35,FIND("/",C35,1)-1)," ",""),"") -> 3.8.120%piperidinesolution | B35: 3.8.1 | C35: 20% piperidine solution/20%哌啶溶液 | D35: - | E35: 0.931 | F35: - | G35: 7.44 | H35: =TEXT(ROUND(G35*树脂信息!$C$4,2),"0.00") -> 483.60 | I35: ±6% | J35: =TEXT(ROUND(H35*0.94,2),"0.00")&"~"&TEXT(ROUND(H35*1.06,2),"0.00") -> 454.58~512.62 | L35: See below/见下行 | P35: 8
A36: =IFERROR(SUBSTITUTE(IFERROR(MID(B36,FIND("/",B36,1)+1,LEN(B36)),B36)&LEFT(C36,FIND("/",C36,1)-1)," ",""),"") -> 3.8.4IPAC | B36: 3.8.4 | C36: IPAC/乙酸异丙酯 | D36: - | E36: 0.873 | F36: - | G36: 6.98 | H36: =TEXT(ROUND(G36*树脂信息!$C$4,2),"0.00") -> 453.70 | I36: ±6% | J36: =TEXT(ROUND(H36*0.94,2),"0.00")&"~"&TEXT(ROUND(H36*1.06,2),"0.00") -> 426.48~480.92 | L36: See below/见下行 | P36: 8
A37: =IFERROR(SUBSTITUTE(IFERROR(MID(B37,FIND("/",B37,1)+1,LEN(B37)),B37)&LEFT(C37,FIND("/",C37,1)-1)," ",""),"") | D37: Qty Charged/实际投料量（kg）：1st： kg；2nd： kg；3rd： kg；
A38: =IFERROR(SUBSTITUTE(IFERROR(MID(B38,FIND("/",B38,1)+1,LEN(B38)),B38)&LEFT(C38,FIND("/",C38,1)-1)," ",""),"") | D38: 4th： kg；
A39: =IFERROR(SUBSTITUTE(IFERROR(MID(B39,FIND("/",B39,1)+1,LEN(B39)),B39)&LEFT(C39,FIND("/",C39,1)-1)," ",""),"") -> 3.8.5DMF | B39: 3.8.5 | C39: DMF/N, N-二甲基甲酰胺 | D39: 73.1 | E39: 0.948 | F39: - | G39: 7.58 | H39: =TEXT(ROUND(G39*树脂信息!$C$4,2),"0.00") -> 492.70 | I39: ±6% | J39: =TEXT(ROUND(H39*0.94,2),"0.00")&"~"&TEXT(ROUND(H39*1.06,2),"0.00") -> 463.14~522.26 | P39: 8
A40: =IFERROR(SUBSTITUTE(IFERROR(MID(B40,FIND("/",B40,1)+1,LEN(B40)),B40)&LEFT(C40,FIND("/",C40,1)-1)," ",""),"") -> 3.8.7DMF | B40: 3.8.7 | C40: DMF/N, N-二甲基甲酰胺 | D40: 73.1 | E40: 0.948 | F40: - | G40: 7.58 | H40: =TEXT(ROUND(G40*树脂信息!$C$4,2),"0.00") -> 492.70 | I40: ±6% | J40: =TEXT(ROUND(H40*0.94,2),"0.00")&"~"&TEXT(ROUND(H40*1.06,2),"0.00") -> 463.14~522.26 | P40: 8
...

Sheet MOR投料表
B1: Operation Instruction No. | C1: Raw Material Name | D1: Density/ | E1: Mol. Wt. of material/ | F1: Volume/Weight Ratio to limiting material/与基准原料质量体积比 | G1: Qty Ratio to limiting material/ | H1: Mol Ratio to limiting | I1: Standard Batch Qty/标准投料量*（kg） | J1: Weighing accuracy/称量精确度 | K1: Acceptable weighing range/可接受称量范围（kg） | L1: 计算标准投料量 | M1: 计算可接受范围 | N1: 标准投料量比对 | O1: 可接受范围比对
A2: =IFERROR(SUBSTITUTE(IFERROR(MID(B2,FIND("/",B2,1)+1,LEN(B2)),B2)&LEFT(C2,FIND("/",C2,1)-1)," ",""),"") -> 3DMF | B2: 3 | C2: DMF/ | D2: 0.95 | E2: 73.1 | F2: 6 | G2: 5.69 | H2: - | I2: 369.85 | J2: ±6% | K2: 347.66~392.04 | L2: =TEXT(VLOOKUP(A2,氨基酸和溶剂信息!A:J,8,FALSE),"0.00") -> 369.85 | M2: =VLOOKUP(A2,氨基酸和溶剂信息!A:J,10,FALSE) -> 347.66~392.04 | N2: =TEXT(L2,"0.00")=TEXT(I2,"0.00") -> TRUE | O2: =K2=M2 -> TRUE
A3: =IFERROR(SUBSTITUTE(IFERROR(MID(B3,FIND("/",B3,1)+1,LEN(B3)),B3)&LEFT(C3,FIND("/",C3,1)-1)," ",""),"") -> 3DMF | B3: 3 | C3: DMF/ | D3: 0.95 | E3: 73.1 | F3: 6 | G3: 5.69 | H3: - | I3: 369.85 | J3: ±6% | K3: 347.66~392.04 | L3: =TEXT(VLOOKUP(A3,氨基酸和溶剂信息!A:J,8,FALSE),"0.00") -> 369.85 | M3: =VLOOKUP(A3,氨基酸和溶剂信息!A:J,10,FALSE) -> 347.66~392.04 | N3: =TEXT(L3,"0.00")=TEXT(I3,"0.00") -> TRUE | O3: =K3=M3 -> TRUE
A4: =IFERROR(SUBSTITUTE(IFERROR(MID(B4,FIND("/",B4,1)+1,LEN(B4)),B4)&LEFT(C4,FIND("/",C4,1)-1)," ",""),"") -> 3.1.3DMF | B4: 3.1.3 | C4: DMF/ | D4: 0.95 | E4: 73.1 | F4: 8 | G4: 7.58 | H4: - | I4: 492.7 | J4: ±6% | K4: 463.14~522.26 | L4: =TEXT(VLOOKUP(A4,氨基酸和溶剂信息!A:J,8,FALSE),"0.00") -> 492.70 | M4: =VLOOKUP(A4,氨基酸和溶剂信息!A:J,10,FALSE) -> 463.14~522.26 | N4: =TEXT(L4,"0.00")=TEXT(I4,"0.00") -> TRUE | O4: =K4=M4 -> TRUE
A5: =IFERROR(SUBSTITUTE(IFERROR(MID(B5,FIND("/",B5,1)+1,LEN(B5)),B5)&LEFT(C5,FIND("/",C5,1)-1)," ",""),"") -> 3.1.6DMF | B5: 3.1.6 | C5: DMF/ | D5: 0.95 | E5: 73.1 | F5: 6 | G5: 5.69 | H5: - | I5: 369.85 | J5: ±5% | K5: 351.36~388.34 | L5: =TEXT(VLOOKUP(A5,氨基酸和溶剂信息!A:J,8,FALSE),"0.00") -> 369.85 | M5: =VLOOKUP(A5,氨基酸和溶剂信息!A:J,10,FALSE) -> 351.36~388.34 | N5: =TEXT(L5,"0.00")=TEXT(I5,"0.00") -> TRUE | O5: =K5=M5 -> TRUE
A6: =IFERROR(SUBSTITUTE(IFERROR(MID(B6,FIND("/",B6,1)+1,LEN(B6)),B6)&LEFT(C6,FIND("/",C6,1)-1)," ",""),"") -> 3.1.7Fmoc-Gly-OH | B6: 1.2/3.1.7 | C6: Fmoc-Gly-OH/ | D6: - | E6: 297.31 | F6: - | G6: - | H6: 2.25 | J6: ±3% | L6: =TEXT(VLOOKUP(A6,氨基酸和溶剂信息!A:J,8,FALSE),"0.00") -> 68.70 | M6: =VLOOKUP(A6,氨基酸和溶剂信息!A:J,10,FALSE) -> 66.64~70.76 | N6: =TEXT(L6,"0.00")=TEXT(I6,"0.00") -> FALSE | O6: =K6=M6 -> FALSE
A7: =IFERROR(SUBSTITUTE(IFERROR(MID(B7,FIND("/",B7,1)+1,LEN(B7)),B7)&LEFT(C7,FIND("/",C7,1)-1)," ",""),"") -> 3.1.8DMF | B7: 3.1.8 | C7: DMF/ | E7: 73.1 | F7: 1 | G7: 0.95 | H7: - | I7: 61.75 | J7: ±6% | K7: 58.05~65.46 | L7: =TEXT(VLOOKUP(A7,氨基酸和溶剂信息!A:J,8,FALSE),"0.00") -> 61.75 | M7: =VLOOKUP(A7,氨基酸和溶剂信息!A:J,10,FALSE) -> 58.05~65.46 | N7: =TEXT(L7,"0.00")=TEXT(I7,"0.00") -> TRUE | O7: =K7=M7 -> TRUE
A8: =IFERROR(SUBSTITUTE(IFERROR(MID(B8,FIND("/",B8,1)+1,LEN(B8)),B8)&LEFT(C8,FIND("/",C8,1)-1)," ",""),"") -> 3.1.9DMF | B8: 3.1.9 | C8: DMF/ | D8: 0.95 | E8: 73.1 | F8: 5 | G8: 4.74 | H8: - | I8: 308.1 | J8: ±6% | K8: 289.61~326.59 | L8: =TEXT(VLOOKUP(A8,氨基酸和溶剂信息!A:J,8,FALSE),"0.00") -> 308.10 | M8: =VLOOKUP(A8,氨基酸和溶剂信息!A:J,10,FALSE) -> 289.61~326.59 | N8: =TEXT(L8,"0.00")=TEXT(I8,"0.00") -> TRUE | O8: =K8=M8 -> TRUE
A9: =IFERROR(SUBSTITUTE(IFERROR(MID(B9,FIND("/",B9,1)+1,LEN(B9)),B9)&LEFT(C9,FIND("/",C9,1)-1)," ",""),"") -> 3.2.1DIPEA | B9: 3.2.1 | C9: DIPEA/ | D9: 0.742 | E9: 129.24 | F9: - | G9: - | H9: 6 | J9: ±3% | L9: =TEXT(VLOOKUP(A9,氨基酸和溶剂信息!A:J,8,FALSE),"0.00") -> 79.64 | M9: =VLOOKUP(A9,氨基酸和溶剂信息!A:J,10,FALSE) -> 77.25~82.03 | N9: =TEXT(L9,"0.00")=TEXT(I9,"0.00") -> FALSE | O9: =K9=M9 -> FALSE
A10: =IFERROR(SUBSTITUTE(IFERROR(MID(B10,FIND("/",B10,1)+1,LEN(B10)),B10)&LEFT(C10,FIND("/",C10,1)-1)," ",""),"") -> 3.3.2DMF | B10: 3.3.2 | C10: DMF/ | D10: 0.95 | E10: 73.1 | F10: 1 | G10: 0.95 | H10: - | I10: 61.75 | J10: ±6% | K10: 58.05~65.46 | L10: =TEXT(VLOOKUP(A10,氨基酸和溶剂信息!A:J,8,FALSE),"0.00") -> 61.75 | M10: =VLOOKUP(A10,氨基酸和溶剂信息!A:J,10,FALSE) -> 58.05~65.46 | N10: =TEXT(L10,"0.00")=TEXT(I10,"0.00") -> TRUE | O10: =K10=M10 -> TRUE
A11: =IFERROR(SUBSTITUTE(IFERROR(MID(B11,FIND("/",B11,1)+1,LEN(B11)),B11)&LEFT(C11,FIND("/",C11,1)-1)," ",""),"") -> 3.3.6DMF | B11: 3.3.6 | C11: DMF/ | D11: 0.95 | E11: 73.1 | F11: 8 | G11: 7.58 | H11: - | I11: 492.7 | J11: ±6% | K11: 463.14~522.26 | L11: =TEXT(VLOOKUP(A11,氨基酸和溶剂信息!A:J,8,FALSE),"0.00") -> 492.70 | M11: =VLOOKUP(A11,氨基酸和溶剂信息!A:J,10,FALSE) -> 463.14~522.26 | N11: =TEXT(L11,"0.00")=TEXT(I11,"0.00") -> TRUE | O11: =K11=M11 -> TRUE
A12: =IFERROR(SUBSTITUTE(IFERROR(MID(B12,FIND("/",B12,1)+1,LEN(B12)),B12)&LEFT(C12,FIND("/",C12,1)-1)," ",""),"") -> 3.4.1DMF | B12: 3.4.1 | C12: DMF/ | D12: 0.95 | E12: 73.1 | F12: 9 | G12: 8.53 | H12: - | I12: 554.45 | J12: ±6% | K12: 521.18~587.72 | L12: =TEXT(VLOOKUP(A12,氨基酸和溶剂信息!A:J,8,FALSE),"0.00") -> 554.45 | M12: =VLOOKUP(A12,氨基酸和溶剂信息!A:J,10,FALSE) -> 521.18~587.72 | N12: =TEXT(L12,"0.00")=TEXT(I12,"0.00") -> TRUE | O12: =K12=M12 -> TRUE
A13: =IFERROR(SUBSTITUTE(IFERROR(MID(B13,FIND("/",B13,1)+1,LEN(B13)),B13)&LEFT(C13,FIND("/",C13,1)-1)," ",""),"") -> 3.4.2Methanol | B13: 3.4.2 | C13: Methanol/ | D13: 0.792 | E13: 32.01 | F13: - | G13: - | H13: 10 | J13: ±3% | L13: =TEXT(VLOOKUP(A13,氨基酸和溶剂信息!A:J,8,FALSE),"0.00") -> 32.87 | M13: =VLOOKUP(A13,氨基酸和溶剂信息!A:J,10,FALSE) -> 31.88~33.86 | N13: =TEXT(L13,"0.00")=TEXT(I13,"0.00") -> FALSE | O13: =K13=M13 -> FALSE
A14: =IFERROR(SUBSTITUTE(IFERROR(MID(B14,FIND("/",B14,1)+1,LEN(B14)),B14)&LEFT(C14,FIND("/",C14,1)-1)," ",""),"") -> 3.4.3DIPEA | B14: 3.4.3 | C14: DIPEA/ | D14: 0.742 | E14: 129.24 | F14: - | G14: - | H14: 5 | J14: ±3% | L14: =TEXT(VLOOKUP(A14,氨基酸和溶剂信息!A:J,8,FALSE),"0.00") -> 66.36 | M14: =VLOOKUP(A14,氨基酸和溶剂信息!A:J,10,FALSE) -> 64.37~68.35 | N14: =TEXT(L14,"0.00")=TEXT(I14,"0.00") -> FALSE | O14: =K14=M14 -> FALSE
A15: =IFERROR(SUBSTITUTE(IFERROR(MID(B15,FIND("/",B15,1)+1,LEN(B15)),B15)&LEFT(C15,FIND("/",C15,1)-1)," ",""),"") -> 3.4.6DMF | B15: 3.4.6 | C15: DMF/ | D15: 0.95 | E15: 73.1 | F15: 8 | G15: 7.58 | H15: - | I15: 492.7 | J15: ±6% | K15: 463.14~522.26 | L15: =TEXT(VLOOKUP(A15,氨基酸和溶剂信息!A:J,8,FALSE),"0.00") -> 492.70 | M15: =VLOOKUP(A15,氨基酸和溶剂信息!A:J,10,FALSE) -> 463.14~522.26 | N15: =TEXT(L15,"0.00")=TEXT(I15,"0.00") -> TRUE | O15: =K15=M15 -> TRUE
A16: =IFERROR(SUBSTITUTE(IFERROR(MID(B16,FIND("/",B16,1)+1,LEN(B16)),B16)&LEFT(C16,FIND("/",C16,1)-1)," ",""),"") -> 3.5.120%Piperidinesolution | B16: 3.5.1 | C16: 20% Piperidine solution/ | D16: 0.931 | E16: - | F16: 8 | G16: 7.44 | H16: - | I16: 483.6 | J16: ±6% | K16: 454.58~512.62 | L16: =TEXT(VLOOKUP(A16,氨基酸和溶剂信息!A:J,8,FALSE),"0.00") -> 483.60 | M16: =VLOOKUP(A16,氨基酸和溶剂信息!A:J,10,FALSE) -> 454.58~512.62 | N16: =TEXT(L16,"0.00")=TEXT(I16,"0.00") -> TRUE | O16: =K16=M16 -> TRUE
A17: =IFERROR(SUBSTITUTE(IFERROR(MID(B17,FIND("/",B17,1)+1,LEN(B17)),B17)&LEFT(C17,FIND("/",C17,1)-1)," ",""),"") -> 3.5.4IPAc | B17: 3.5.4 | C17: IPAc/ | D17: 0.873 | E17: 102.13 | F17: 8 | G17: 6.98 | H17: - | I17: 453.7 | J17: ±6% | K17: 426.48~480.92 | L17: =TEXT(VLOOKUP(A17,氨基酸和溶剂信息!A:J,8,FALSE),"0.00") -> 453.70 | M17: =VLOOKUP(A17,氨基酸和溶剂信息!A:J,10,FALSE) -> 426.48~480.92 | N17: =TEXT(L17,"0.00")=TEXT(I17,"0.00") -> TRUE | O17: =K17=M17 -> TRUE
A18: =IFERROR(SUBSTITUTE(IFERROR(MID(B18,FIND("/",B18,1)+1,LEN(B18)),B18)&LEFT(C18,FIND("/",C18,1)-1)," ",""),"") -> 3.5.5DMF | B18: 3.5.5 | C18: DMF/ | D18: 0.95 | E18: 73.1 | F18: 8 | G18: 7.58 | H18: - | I18: 492.7 | J18: ±6% | K18: 463.14~522.26 | L18: =TEXT(VLOOKUP(A18,氨基酸和溶剂信息!A:J,8,FALSE),"0.00") -> 492.70 | M18: =VLOOKUP(A18,氨基酸和溶剂信息!A:J,10,FALSE) -> 463.14~522.26 | N18: =TEXT(L18,"0.00")=TEXT(I18,"0.00") -> TRUE | O18: =K18=M18 -> TRUE
A19: =IFERROR(SUBSTITUTE(IFERROR(MID(B19,FIND("/",B19,1)+1,LEN(B19)),B19)&LEFT(C19,FIND("/",C19,1)-1)," ",""),"") -> 3.5.7DMF | B19: 3.5.7 | C19: DMF/ | D19: 0.95 | E19: 73.1 | F19: 8 | G19: 7.58 | H19: - | I19: 492.7 | J19: ±6% | K19: 463.14~522.26 | L19: =TEXT(VLOOKUP(A19,氨基酸和溶剂信息!A:J,8,FALSE),"0.00") -> 492.70 | M19: =VLOOKUP(A19,氨基酸和溶剂信息!A:J,10,FALSE) -> 463.14~522.26 | N19: =TEXT(L19,"0.00")=TEXT(I19,"0.00") -> TRUE | O19: =K19=M19 -> TRUE
A20: =IFERROR(SUBSTITUTE(IFERROR(MID(B20,FIND("/",B20,1)+1,LEN(B20)),B20)&LEFT(C20,FIND("/",C20,1)-1)," ",""),"") -> 3.6.1DMF | B20: 3.6.1 | C20: DMF/ | D20: 0.95 | E20: 73.1 | F20: 4 | G20: 3.79 | H20: - | I20: 246.35 | J20: ±5% | K20: 234.03~258.67 | L20: =TEXT(VLOOKUP(A20,氨基酸和溶剂信息!A:J,8,FALSE),"0.00") -> 246.35 | M20: =VLOOKUP(A20,氨基酸和溶剂信息!A:J,10,FALSE) -> 234.03~258.67 | N20: =TEXT(L20,"0.00")=TEXT(I20,"0.00") -> TRUE | O20: =K20=M20 -> TRUE
A21: =IFERROR(SUBSTITUTE(IFERROR(MID(B21,FIND("/",B21,1)+1,LEN(B21)),B21)&LEFT(C21,FIND("/",C21,1)-1)," ",""),"") -> 3.6.2Fmoc-L-Thr(tBu)-OH | B21: 1.3/3.6.2 | C21: Fmoc-L-Thr(tBu)-OH/ | D21: - | E21: 397.47 | F21: - | G21: - | H21: 2 | J21: ±3% | L21: =TEXT(VLOOKUP(A21,氨基酸和溶剂信息!A:J,8,FALSE),"0.00") -> 81.64 | M21: =VLOOKUP(A21,氨基酸和溶剂信息!A:J,10,FALSE) -> 79.19~84.09 | N21: =TEXT(L21,"0.00")=TEXT(I21,"0.00") -> FALSE | O21: =K21=M21 -> FALSE
A22: =IFERROR(SUBSTITUTE(IFERROR(MID(B22,FIND("/",B22,1)+1,LEN(B22)),B22)&LEFT(C22,FIND("/",C22,1)-1)," ",""),"") -> 3.6.4PyBOP | B22: 1.4/3.6.4 | C22: PyBOP/ | D22: - | E22: 520.39 | F22: - | G22: - | H22: 2 | J22: ±3% | L22: =TEXT(VLOOKUP(A22,氨基酸和溶剂信息!A:J,8,FALSE),"0.00") -> 106.89 | M22: =VLOOKUP(A22,氨基酸和溶剂信息!A:J,10,FALSE) -> 103.68~110.10 | N22: =TEXT(L22,"0.00")=TEXT(I22,"0.00") -> FALSE | O22: =K22=M22 -> FALSE
A23: =IFERROR(SUBSTITUTE(IFERROR(MID(B23,FIND("/",B23,1)+1,LEN(B23)),B23)&LEFT(C23,FIND("/",C23,1)-1)," ",""),"") -> 3.6.5OxymaPure | B23: 1.5/3.6.5 | C23: Oxyma Pure/ | D23: - | E23: 142.11 | F23: - | G23: - | H23: 2 | J23: ±3% | L23: =TEXT(VLOOKUP(A23,氨基酸和溶剂信息!A:J,8,FALSE),"0.00") -> 29.19 | M23: =VLOOKUP(A23,氨基酸和溶剂信息!A:J,10,FALSE) -> 28.31~30.07 | N23: =TEXT(L23,"0.00")=TEXT(I23,"0.00") -> FALSE | O23: =K23=M23 -> FALSE
A24: =IFERROR(SUBSTITUTE(IFERROR(MID(B24,FIND("/",B24,1)+1,LEN(B24)),B24)&LEFT(C24,FIND("/",C24,1)-1)," ",""),"") -> 3.6.6DMF | B24: 3.6.6 | C24: DMF/ | D24: 0.95 | E24: 73.1 | F24: 1 | G24: 0.95 | H24: - | I24: 61.75 | J24: ±6% | K24: 58.05~65.46 | L24: =TEXT(VLOOKUP(A24,氨基酸和溶剂信息!A:J,8,FALSE),"0.00") -> 61.75 | M24: =VLOOKUP(A24,氨基酸和溶剂信息!A:J,10,FALSE) -> 58.05~65.46 | N24: =TEXT(L24,"0.00")=TEXT(I24,"0.00") -> TRUE | O24: =K24=M24 -> TRUE
A25: =IFERROR(SUBSTITUTE(IFERROR(MID(B25,FIND("/",B25,1)+1,LEN(B25)),B25)&LEFT(C25,FIND("/",C25,1)-1)," ",""),"") -> 3.6.7DIPEA | B25: 3.6.7 | C25: DIPEA/ | D25: 0.742 | E25: 129.24 | F25: - | G25: - | H25: 3 | J25: ±3% | L25: =TEXT(VLOOKUP(A25,氨基酸和溶剂信息!A:J,8,FALSE),"0.00") -> 39.82 | M25: =VLOOKUP(A25,氨基酸和溶剂信息!A:J,10,FALSE) -> 38.63~41.01 | N25: =TEXT(L25,"0.00")=TEXT(I25,"0.00") -> FALSE | O25: =K25=M25 -> FALSE
A26: =IFERROR(SUBSTITUTE(IFERROR(MID(B26,FIND("/",B26,1)+1,LEN(B26)),B26)&LEFT(C26,FIND("/",C26,1)-1)," ",""),"") -> 3.7.1DMF | B26: 3.7.1 | C26: DMF/ | D26: 0.95 | E26: 73.1 | F26: 3 | G26: 2.84 | H26: - | I26: 184.6 | J26: ±6% | K26: 173.52~195.68 | L26: =TEXT(VLOOKUP(A26,氨基酸和溶剂信息!A:J,8,FALSE),"0.00") -> 184.60 | M26: =VLOOKUP(A26,氨基酸和溶剂信息!A:J,10,FALSE) -> 173.52~195.68 | N26: =TEXT(L26,"0.00")=TEXT(I26,"0.00") -> TRUE | O26: =K26=M26 -> TRUE
